Watching for file changes with StatReloader
Watching for file changes with StatReloader
Internal Server Error: /
Traceback (most recent call last):
  File "/Users/malenkijkotik/Desktop/progs/rsoi/env/lib/python3.7/site-packages/django/core/handlers/exception.py", line 34, in inner
    response = get_response(request)
  File "/Users/malenkijkotik/Desktop/progs/rsoi/env/lib/python3.7/site-packages/django/core/handlers/base.py", line 115, in _get_response
    response = self.process_exception_by_middleware(e, request)
  File "/Users/malenkijkotik/Desktop/progs/rsoi/env/lib/python3.7/site-packages/django/core/handlers/base.py", line 113, in _get_response
    response = wrapped_callback(request, *callback_args, **callback_kwargs)
  File "/Users/malenkijkotik/Desktop/progs/rsoi/env/lib/python3.7/site-packages/django/views/decorators/csrf.py", line 54, in wrapped_view
    return view_func(*args, **kwargs)
  File "/Users/malenkijkotik/Desktop/progs/rsoi/env/lib/python3.7/site-packages/django/views/generic/base.py", line 71, in view
    return self.dispatch(request, *args, **kwargs)
  File "/Users/malenkijkotik/Desktop/progs/rsoi/env/lib/python3.7/site-packages/rest_framework/views.py", line 497, in dispatch
    response = self.handle_exception(exc)
  File "/Users/malenkijkotik/Desktop/progs/rsoi/env/lib/python3.7/site-packages/rest_framework/views.py", line 457, in handle_exception
    self.raise_uncaught_exception(exc)
  File "/Users/malenkijkotik/Desktop/progs/rsoi/env/lib/python3.7/site-packages/rest_framework/views.py", line 468, in raise_uncaught_exception
    raise exc
  File "/Users/malenkijkotik/Desktop/progs/rsoi/env/lib/python3.7/site-packages/rest_framework/views.py", line 494, in dispatch
    response = handler(request, *args, **kwargs)
  File "/Users/malenkijkotik/Desktop/progs/rsoi-online-store/online-store-customers/customers_app/views.py", line 50, in get
    customer['orders'][i] = order_response[0].json()
AttributeError: 'str' object has no attribute 'json'
"GET / HTTP/1.1" 500 93515
"GET /admin/ HTTP/1.1" 302 0
"GET /admin/login/?next=/admin/ HTTP/1.1" 200 1913
"GET /static/admin/css/base.css HTTP/1.1" 200 16378
"GET /static/admin/css/login.css HTTP/1.1" 200 1233
"GET /static/admin/css/responsive.css HTTP/1.1" 200 18052
"GET /static/admin/css/fonts.css HTTP/1.1" 200 423
"GET /static/admin/fonts/Roboto-Regular-webfont.woff HTTP/1.1" 200 85876
"GET /static/admin/fonts/Roboto-Light-webfont.woff HTTP/1.1" 200 85692
"POST /admin/login/?next=/admin/ HTTP/1.1" 302 0
Watching for file changes with StatReloader
Watching for file changes with StatReloader
Watching for file changes with StatReloader
/Users/malenkijkotik/Desktop/progs/rsoi-online-store/online-store-customers/customers_app/views.py changed, reloading.
Watching for file changes with StatReloader
/Users/malenkijkotik/Desktop/progs/rsoi-online-store/online-store-customers/customers_app/models.py changed, reloading.
Watching for file changes with StatReloader
Watching for file changes with StatReloader
Not Found: /
"GET / HTTP/1.1" 404 2420
Not Found: /
"GET / HTTP/1.1" 404 2420
Not Found: /favicon.ico
"GET /favicon.ico HTTP/1.1" 404 2471
"GET /all_customers HTTP/1.1" 301 0
Internal Server Error: /all_customers/
Traceback (most recent call last):
  File "/Users/malenkijkotik/Desktop/progs/rsoi/env/lib/python3.7/site-packages/django/db/backends/utils.py", line 84, in _execute
    return self.cursor.execute(sql, params)
psycopg2.errors.UndefinedColumn: column customers_app_customer.id does not exist
LINE 1: SELECT "customers_app_customer"."id", "customers_app_custome...
               ^


The above exception was the direct cause of the following exception:

Traceback (most recent call last):
  File "/Users/malenkijkotik/Desktop/progs/rsoi/env/lib/python3.7/site-packages/django/core/handlers/exception.py", line 34, in inner
    response = get_response(request)
  File "/Users/malenkijkotik/Desktop/progs/rsoi/env/lib/python3.7/site-packages/django/core/handlers/base.py", line 115, in _get_response
    response = self.process_exception_by_middleware(e, request)
  File "/Users/malenkijkotik/Desktop/progs/rsoi/env/lib/python3.7/site-packages/django/core/handlers/base.py", line 113, in _get_response
    response = wrapped_callback(request, *callback_args, **callback_kwargs)
  File "/Users/malenkijkotik/Desktop/progs/rsoi/env/lib/python3.7/site-packages/django/views/decorators/csrf.py", line 54, in wrapped_view
    return view_func(*args, **kwargs)
  File "/Users/malenkijkotik/Desktop/progs/rsoi/env/lib/python3.7/site-packages/django/views/generic/base.py", line 71, in view
    return self.dispatch(request, *args, **kwargs)
  File "/Users/malenkijkotik/Desktop/progs/rsoi/env/lib/python3.7/site-packages/rest_framework/views.py", line 497, in dispatch
    response = self.handle_exception(exc)
  File "/Users/malenkijkotik/Desktop/progs/rsoi/env/lib/python3.7/site-packages/rest_framework/views.py", line 457, in handle_exception
    self.raise_uncaught_exception(exc)
  File "/Users/malenkijkotik/Desktop/progs/rsoi/env/lib/python3.7/site-packages/rest_framework/views.py", line 468, in raise_uncaught_exception
    raise exc
  File "/Users/malenkijkotik/Desktop/progs/rsoi/env/lib/python3.7/site-packages/rest_framework/views.py", line 494, in dispatch
    response = handler(request, *args, **kwargs)
  File "/Users/malenkijkotik/Desktop/progs/rsoi-online-store/online-store-customers/customers_app/views.py", line 27, in get
    serialized_customers = [CustomerSerializer(customer).data for customer in customers]
  File "/Users/malenkijkotik/Desktop/progs/rsoi/env/lib/python3.7/site-packages/django/db/models/query.py", line 274, in __iter__
    self._fetch_all()
  File "/Users/malenkijkotik/Desktop/progs/rsoi/env/lib/python3.7/site-packages/django/db/models/query.py", line 1242, in _fetch_all
    self._result_cache = list(self._iterable_class(self))
  File "/Users/malenkijkotik/Desktop/progs/rsoi/env/lib/python3.7/site-packages/django/db/models/query.py", line 55, in __iter__
    results = compiler.execute_sql(chunked_fetch=self.chunked_fetch, chunk_size=self.chunk_size)
  File "/Users/malenkijkotik/Desktop/progs/rsoi/env/lib/python3.7/site-packages/django/db/models/sql/compiler.py", line 1140, in execute_sql
    cursor.execute(sql, params)
  File "/Users/malenkijkotik/Desktop/progs/rsoi/env/lib/python3.7/site-packages/django/db/backends/utils.py", line 99, in execute
    return super().execute(sql, params)
  File "/Users/malenkijkotik/Desktop/progs/rsoi/env/lib/python3.7/site-packages/django/db/backends/utils.py", line 67, in execute
    return self._execute_with_wrappers(sql, params, many=False, executor=self._execute)
  File "/Users/malenkijkotik/Desktop/progs/rsoi/env/lib/python3.7/site-packages/django/db/backends/utils.py", line 76, in _execute_with_wrappers
    return executor(sql, params, many, context)
  File "/Users/malenkijkotik/Desktop/progs/rsoi/env/lib/python3.7/site-packages/django/db/backends/utils.py", line 84, in _execute
    return self.cursor.execute(sql, params)
  File "/Users/malenkijkotik/Desktop/progs/rsoi/env/lib/python3.7/site-packages/django/db/utils.py", line 89, in __exit__
    raise dj_exc_value.with_traceback(traceback) from exc_value
  File "/Users/malenkijkotik/Desktop/progs/rsoi/env/lib/python3.7/site-packages/django/db/backends/utils.py", line 84, in _execute
    return self.cursor.execute(sql, params)
django.db.utils.ProgrammingError: column customers_app_customer.id does not exist
LINE 1: SELECT "customers_app_customer"."id", "customers_app_custome...
               ^

"GET /all_customers/ HTTP/1.1" 500 142413
Watching for file changes with StatReloader
Internal Server Error: /all_customers/
Traceback (most recent call last):
  File "/Users/malenkijkotik/Desktop/progs/rsoi/env/lib/python3.7/site-packages/django/db/backends/utils.py", line 84, in _execute
    return self.cursor.execute(sql, params)
psycopg2.errors.UndefinedColumn: column customers_app_customer.id does not exist
LINE 1: SELECT "customers_app_customer"."id", "customers_app_custome...
               ^


The above exception was the direct cause of the following exception:

Traceback (most recent call last):
  File "/Users/malenkijkotik/Desktop/progs/rsoi/env/lib/python3.7/site-packages/django/core/handlers/exception.py", line 34, in inner
    response = get_response(request)
  File "/Users/malenkijkotik/Desktop/progs/rsoi/env/lib/python3.7/site-packages/django/core/handlers/base.py", line 115, in _get_response
    response = self.process_exception_by_middleware(e, request)
  File "/Users/malenkijkotik/Desktop/progs/rsoi/env/lib/python3.7/site-packages/django/core/handlers/base.py", line 113, in _get_response
    response = wrapped_callback(request, *callback_args, **callback_kwargs)
  File "/Users/malenkijkotik/Desktop/progs/rsoi/env/lib/python3.7/site-packages/django/views/decorators/csrf.py", line 54, in wrapped_view
    return view_func(*args, **kwargs)
  File "/Users/malenkijkotik/Desktop/progs/rsoi/env/lib/python3.7/site-packages/django/views/generic/base.py", line 71, in view
    return self.dispatch(request, *args, **kwargs)
  File "/Users/malenkijkotik/Desktop/progs/rsoi/env/lib/python3.7/site-packages/rest_framework/views.py", line 497, in dispatch
    response = self.handle_exception(exc)
  File "/Users/malenkijkotik/Desktop/progs/rsoi/env/lib/python3.7/site-packages/rest_framework/views.py", line 457, in handle_exception
    self.raise_uncaught_exception(exc)
  File "/Users/malenkijkotik/Desktop/progs/rsoi/env/lib/python3.7/site-packages/rest_framework/views.py", line 468, in raise_uncaught_exception
    raise exc
  File "/Users/malenkijkotik/Desktop/progs/rsoi/env/lib/python3.7/site-packages/rest_framework/views.py", line 494, in dispatch
    response = handler(request, *args, **kwargs)
  File "/Users/malenkijkotik/Desktop/progs/rsoi-online-store/online-store-customers/customers_app/views.py", line 27, in get
    serialized_customers = [CustomerSerializer(customer).data for customer in customers]
  File "/Users/malenkijkotik/Desktop/progs/rsoi/env/lib/python3.7/site-packages/django/db/models/query.py", line 274, in __iter__
    self._fetch_all()
  File "/Users/malenkijkotik/Desktop/progs/rsoi/env/lib/python3.7/site-packages/django/db/models/query.py", line 1242, in _fetch_all
    self._result_cache = list(self._iterable_class(self))
  File "/Users/malenkijkotik/Desktop/progs/rsoi/env/lib/python3.7/site-packages/django/db/models/query.py", line 55, in __iter__
    results = compiler.execute_sql(chunked_fetch=self.chunked_fetch, chunk_size=self.chunk_size)
  File "/Users/malenkijkotik/Desktop/progs/rsoi/env/lib/python3.7/site-packages/django/db/models/sql/compiler.py", line 1140, in execute_sql
    cursor.execute(sql, params)
  File "/Users/malenkijkotik/Desktop/progs/rsoi/env/lib/python3.7/site-packages/django/db/backends/utils.py", line 99, in execute
    return super().execute(sql, params)
  File "/Users/malenkijkotik/Desktop/progs/rsoi/env/lib/python3.7/site-packages/django/db/backends/utils.py", line 67, in execute
    return self._execute_with_wrappers(sql, params, many=False, executor=self._execute)
  File "/Users/malenkijkotik/Desktop/progs/rsoi/env/lib/python3.7/site-packages/django/db/backends/utils.py", line 76, in _execute_with_wrappers
    return executor(sql, params, many, context)
  File "/Users/malenkijkotik/Desktop/progs/rsoi/env/lib/python3.7/site-packages/django/db/backends/utils.py", line 84, in _execute
    return self.cursor.execute(sql, params)
  File "/Users/malenkijkotik/Desktop/progs/rsoi/env/lib/python3.7/site-packages/django/db/utils.py", line 89, in __exit__
    raise dj_exc_value.with_traceback(traceback) from exc_value
  File "/Users/malenkijkotik/Desktop/progs/rsoi/env/lib/python3.7/site-packages/django/db/backends/utils.py", line 84, in _execute
    return self.cursor.execute(sql, params)
django.db.utils.ProgrammingError: column customers_app_customer.id does not exist
LINE 1: SELECT "customers_app_customer"."id", "customers_app_custome...
               ^

"GET /all_customers/ HTTP/1.1" 500 142346
Not Found: /favicon.ico
"GET /favicon.ico HTTP/1.1" 404 2471
/Users/malenkijkotik/Desktop/progs/rsoi-online-store/online-store-customers/customers_app/migrations/0001_initial.py changed, reloading.
Watching for file changes with StatReloader
/Users/malenkijkotik/Desktop/progs/rsoi-online-store/online-store-customers/customers_app/models.py changed, reloading.
Watching for file changes with StatReloader
Internal Server Error: /all_customers/
Traceback (most recent call last):
  File "/Users/malenkijkotik/Desktop/progs/rsoi/env/lib/python3.7/site-packages/django/core/handlers/exception.py", line 34, in inner
    response = get_response(request)
  File "/Users/malenkijkotik/Desktop/progs/rsoi/env/lib/python3.7/site-packages/django/core/handlers/base.py", line 145, in _get_response
    response = self.process_exception_by_middleware(e, request)
  File "/Users/malenkijkotik/Desktop/progs/rsoi/env/lib/python3.7/site-packages/django/core/handlers/base.py", line 143, in _get_response
    response = response.render()
  File "/Users/malenkijkotik/Desktop/progs/rsoi/env/lib/python3.7/site-packages/django/template/response.py", line 106, in render
    self.content = self.rendered_content
  File "/Users/malenkijkotik/Desktop/progs/rsoi/env/lib/python3.7/site-packages/rest_framework/response.py", line 70, in rendered_content
    ret = renderer.render(self.data, accepted_media_type, context)
  File "/Users/malenkijkotik/Desktop/progs/rsoi/env/lib/python3.7/site-packages/rest_framework/renderers.py", line 725, in render
    context = self.get_context(data, accepted_media_type, renderer_context)
  File "/Users/malenkijkotik/Desktop/progs/rsoi/env/lib/python3.7/site-packages/rest_framework/renderers.py", line 699, in get_context
    'options_form': self.get_rendered_html_form(data, view, 'OPTIONS', request),
  File "/Users/malenkijkotik/Desktop/progs/rsoi/env/lib/python3.7/site-packages/rest_framework/renderers.py", line 477, in get_rendered_html_form
    if not self.show_form_for_method(view, method, request, instance):
  File "/Users/malenkijkotik/Desktop/progs/rsoi/env/lib/python3.7/site-packages/rest_framework/renderers.py", line 432, in show_form_for_method
    view.check_permissions(request)
  File "/Users/malenkijkotik/Desktop/progs/rsoi/env/lib/python3.7/site-packages/rest_framework/views.py", line 332, in check_permissions
    if not permission.has_permission(request, self):
  File "/Users/malenkijkotik/Desktop/progs/rsoi-online-store/online-store-customers/customers_app/permissions.py", line 27, in has_permission
    response, status_code = r.get_user_info(r.get_token_from_request(request))
  File "/Users/malenkijkotik/Desktop/progs/rsoi-online-store/online-store-customers/customers_app/requesters/authrequester.py", line 12, in get_user_info
    token = self.get_token_from_request(request)
  File "/Users/malenkijkotik/Desktop/progs/rsoi-online-store/online-store-customers/customers_app/requesters/requester.py", line 75, in get_token_from_request
    token_str = request.META.get('HTTP_AUTHORIZATION')
AttributeError: 'NoneType' object has no attribute 'META'
"GET /all_customers/ HTTP/1.1" 500 106633
Internal Server Error: /all_customers/
Traceback (most recent call last):
  File "/Users/malenkijkotik/Desktop/progs/rsoi/env/lib/python3.7/site-packages/django/core/handlers/exception.py", line 34, in inner
    response = get_response(request)
  File "/Users/malenkijkotik/Desktop/progs/rsoi/env/lib/python3.7/site-packages/django/core/handlers/base.py", line 145, in _get_response
    response = self.process_exception_by_middleware(e, request)
  File "/Users/malenkijkotik/Desktop/progs/rsoi/env/lib/python3.7/site-packages/django/core/handlers/base.py", line 143, in _get_response
    response = response.render()
  File "/Users/malenkijkotik/Desktop/progs/rsoi/env/lib/python3.7/site-packages/django/template/response.py", line 106, in render
    self.content = self.rendered_content
  File "/Users/malenkijkotik/Desktop/progs/rsoi/env/lib/python3.7/site-packages/rest_framework/response.py", line 70, in rendered_content
    ret = renderer.render(self.data, accepted_media_type, context)
  File "/Users/malenkijkotik/Desktop/progs/rsoi/env/lib/python3.7/site-packages/rest_framework/renderers.py", line 725, in render
    context = self.get_context(data, accepted_media_type, renderer_context)
  File "/Users/malenkijkotik/Desktop/progs/rsoi/env/lib/python3.7/site-packages/rest_framework/renderers.py", line 699, in get_context
    'options_form': self.get_rendered_html_form(data, view, 'OPTIONS', request),
  File "/Users/malenkijkotik/Desktop/progs/rsoi/env/lib/python3.7/site-packages/rest_framework/renderers.py", line 477, in get_rendered_html_form
    if not self.show_form_for_method(view, method, request, instance):
  File "/Users/malenkijkotik/Desktop/progs/rsoi/env/lib/python3.7/site-packages/rest_framework/renderers.py", line 432, in show_form_for_method
    view.check_permissions(request)
  File "/Users/malenkijkotik/Desktop/progs/rsoi/env/lib/python3.7/site-packages/rest_framework/views.py", line 332, in check_permissions
    if not permission.has_permission(request, self):
  File "/Users/malenkijkotik/Desktop/progs/rsoi-online-store/online-store-customers/customers_app/permissions.py", line 27, in has_permission
    response, status_code = r.get_user_info(r.get_token_from_request(request))
  File "/Users/malenkijkotik/Desktop/progs/rsoi-online-store/online-store-customers/customers_app/requesters/authrequester.py", line 12, in get_user_info
    token = self.get_token_from_request(request)
  File "/Users/malenkijkotik/Desktop/progs/rsoi-online-store/online-store-customers/customers_app/requesters/requester.py", line 75, in get_token_from_request
    token_str = request.META.get('HTTP_AUTHORIZATION')
AttributeError: 'NoneType' object has no attribute 'META'
"GET /all_customers/ HTTP/1.1" 500 106633
/Users/malenkijkotik/Desktop/progs/rsoi-online-store/online-store-customers/customers_app/requesters/requester.py changed, reloading.
Watching for file changes with StatReloader
/Users/malenkijkotik/Desktop/progs/rsoi-online-store/online-store-customers/customers_app/requesters/requester.py changed, reloading.
Watching for file changes with StatReloader
Internal Server Error: /all_customers/
Traceback (most recent call last):
  File "/Users/malenkijkotik/Desktop/progs/rsoi/env/lib/python3.7/site-packages/django/core/handlers/exception.py", line 34, in inner
    response = get_response(request)
  File "/Users/malenkijkotik/Desktop/progs/rsoi/env/lib/python3.7/site-packages/django/core/handlers/base.py", line 145, in _get_response
    response = self.process_exception_by_middleware(e, request)
  File "/Users/malenkijkotik/Desktop/progs/rsoi/env/lib/python3.7/site-packages/django/core/handlers/base.py", line 143, in _get_response
    response = response.render()
  File "/Users/malenkijkotik/Desktop/progs/rsoi/env/lib/python3.7/site-packages/django/template/response.py", line 106, in render
    self.content = self.rendered_content
  File "/Users/malenkijkotik/Desktop/progs/rsoi/env/lib/python3.7/site-packages/rest_framework/response.py", line 70, in rendered_content
    ret = renderer.render(self.data, accepted_media_type, context)
  File "/Users/malenkijkotik/Desktop/progs/rsoi/env/lib/python3.7/site-packages/rest_framework/renderers.py", line 725, in render
    context = self.get_context(data, accepted_media_type, renderer_context)
  File "/Users/malenkijkotik/Desktop/progs/rsoi/env/lib/python3.7/site-packages/rest_framework/renderers.py", line 699, in get_context
    'options_form': self.get_rendered_html_form(data, view, 'OPTIONS', request),
  File "/Users/malenkijkotik/Desktop/progs/rsoi/env/lib/python3.7/site-packages/rest_framework/renderers.py", line 477, in get_rendered_html_form
    if not self.show_form_for_method(view, method, request, instance):
  File "/Users/malenkijkotik/Desktop/progs/rsoi/env/lib/python3.7/site-packages/rest_framework/renderers.py", line 432, in show_form_for_method
    view.check_permissions(request)
  File "/Users/malenkijkotik/Desktop/progs/rsoi/env/lib/python3.7/site-packages/rest_framework/views.py", line 332, in check_permissions
    if not permission.has_permission(request, self):
  File "/Users/malenkijkotik/Desktop/progs/rsoi-online-store/online-store-customers/customers_app/permissions.py", line 27, in has_permission
    response, status_code = r.get_user_info(r.get_token_from_request(request))
  File "/Users/malenkijkotik/Desktop/progs/rsoi-online-store/online-store-customers/customers_app/requesters/authrequester.py", line 12, in get_user_info
    token = self.get_token_from_request(request)
  File "/Users/malenkijkotik/Desktop/progs/rsoi-online-store/online-store-customers/customers_app/requesters/requester.py", line 54, in get_token_from_request
    token = request.META['HTTP_AUTHORIZATION']
AttributeError: 'NoneType' object has no attribute 'META'
"GET /all_customers/ HTTP/1.1" 500 106781
/Users/malenkijkotik/Desktop/progs/rsoi-online-store/online-store-customers/customers_app/requesters/requester.py changed, reloading.
Watching for file changes with StatReloader
/Users/malenkijkotik/Desktop/progs/rsoi-online-store/online-store-customers/customers_app/requesters/requester.py changed, reloading.
Watching for file changes with StatReloader
Internal Server Error: /all_customers/
Traceback (most recent call last):
  File "/Users/malenkijkotik/Desktop/progs/rsoi/env/lib/python3.7/site-packages/django/core/handlers/exception.py", line 34, in inner
    response = get_response(request)
  File "/Users/malenkijkotik/Desktop/progs/rsoi/env/lib/python3.7/site-packages/django/core/handlers/base.py", line 145, in _get_response
    response = self.process_exception_by_middleware(e, request)
  File "/Users/malenkijkotik/Desktop/progs/rsoi/env/lib/python3.7/site-packages/django/core/handlers/base.py", line 143, in _get_response
    response = response.render()
  File "/Users/malenkijkotik/Desktop/progs/rsoi/env/lib/python3.7/site-packages/django/template/response.py", line 106, in render
    self.content = self.rendered_content
  File "/Users/malenkijkotik/Desktop/progs/rsoi/env/lib/python3.7/site-packages/rest_framework/response.py", line 70, in rendered_content
    ret = renderer.render(self.data, accepted_media_type, context)
  File "/Users/malenkijkotik/Desktop/progs/rsoi/env/lib/python3.7/site-packages/rest_framework/renderers.py", line 725, in render
    context = self.get_context(data, accepted_media_type, renderer_context)
  File "/Users/malenkijkotik/Desktop/progs/rsoi/env/lib/python3.7/site-packages/rest_framework/renderers.py", line 699, in get_context
    'options_form': self.get_rendered_html_form(data, view, 'OPTIONS', request),
  File "/Users/malenkijkotik/Desktop/progs/rsoi/env/lib/python3.7/site-packages/rest_framework/renderers.py", line 477, in get_rendered_html_form
    if not self.show_form_for_method(view, method, request, instance):
  File "/Users/malenkijkotik/Desktop/progs/rsoi/env/lib/python3.7/site-packages/rest_framework/renderers.py", line 432, in show_form_for_method
    view.check_permissions(request)
  File "/Users/malenkijkotik/Desktop/progs/rsoi/env/lib/python3.7/site-packages/rest_framework/views.py", line 332, in check_permissions
    if not permission.has_permission(request, self):
  File "/Users/malenkijkotik/Desktop/progs/rsoi-online-store/online-store-customers/customers_app/permissions.py", line 27, in has_permission
    response, status_code = r.get_user_info(r.get_token_from_request(request))
  File "/Users/malenkijkotik/Desktop/progs/rsoi-online-store/online-store-customers/customers_app/requesters/authrequester.py", line 12, in get_user_info
    token = self.get_token_from_request(request)
  File "/Users/malenkijkotik/Desktop/progs/rsoi-online-store/online-store-customers/customers_app/requesters/requester.py", line 46, in get_token_from_request
    token = request.META['HTTP_AUTHORIZATION']
AttributeError: 'NoneType' object has no attribute 'META'
"GET /all_customers/ HTTP/1.1" 500 106646
/Users/malenkijkotik/Desktop/progs/rsoi-online-store/online-store-customers/customers_app/requesters/authrequester.py changed, reloading.
Watching for file changes with StatReloader
/Users/malenkijkotik/Desktop/progs/rsoi-online-store/online-store-customers/customers_app/requesters/authrequester.py changed, reloading.
Watching for file changes with StatReloader
/Users/malenkijkotik/Desktop/progs/rsoi-online-store/online-store-customers/customers_app/views.py changed, reloading.
Watching for file changes with StatReloader
"GET /all_customers/ HTTP/1.1" 200 9637
"GET /static/rest_framework/css/prettify.css HTTP/1.1" 200 817
"GET /static/rest_framework/css/bootstrap-tweaks.css HTTP/1.1" 200 3385
"GET /static/rest_framework/css/default.css HTTP/1.1" 200 1131
"GET /static/rest_framework/js/jquery-3.4.1.min.js HTTP/1.1" 200 88145
"GET /static/rest_framework/js/bootstrap.min.js HTTP/1.1" 200 37608
"GET /static/rest_framework/js/prettify-min.js HTTP/1.1" 200 13632
"GET /static/rest_framework/js/ajax-form.js HTTP/1.1" 200 3597
"GET /static/rest_framework/css/bootstrap.min.css HTTP/1.1" 200 121457
"GET /static/rest_framework/js/csrf.js HTTP/1.1" 200 1719
"GET /static/rest_framework/js/default.js HTTP/1.1" 200 1268
"GET /static/rest_framework/img/grid.png HTTP/1.1" 200 1458
Not Found: /favicon.ico
"GET /favicon.ico HTTP/1.1" 404 2471
"GET /all_customers/?format=json HTTP/1.1" 200 2
Not Found: /
"GET / HTTP/1.1" 404 2420
Not Found: /customers_app
"GET /customers_app HTTP/1.1" 404 2477
"GET /all_customers HTTP/1.1" 301 0
"GET /all_customers/ HTTP/1.1" 200 2
/Users/malenkijkotik/Desktop/progs/rsoi-online-store/online-store-customers/customers_app/views.py changed, reloading.
Watching for file changes with StatReloader
/Users/malenkijkotik/Desktop/progs/rsoi-online-store/online-store-customers/customers_app/views.py changed, reloading.
Watching for file changes with StatReloader
Internal Server Error: /register
Traceback (most recent call last):
  File "/Users/malenkijkotik/Desktop/progs/rsoi/env/lib/python3.7/site-packages/django/core/handlers/exception.py", line 34, in inner
    response = get_response(request)
  File "/Users/malenkijkotik/Desktop/progs/rsoi/env/lib/python3.7/site-packages/django/utils/deprecation.py", line 93, in __call__
    response = self.process_request(request)
  File "/Users/malenkijkotik/Desktop/progs/rsoi/env/lib/python3.7/site-packages/django/middleware/common.py", line 53, in process_request
    path = self.get_full_path_with_slash(request)
  File "/Users/malenkijkotik/Desktop/progs/rsoi/env/lib/python3.7/site-packages/django/middleware/common.py", line 93, in get_full_path_with_slash
    'url': request.get_host() + new_path,
RuntimeError: You called this URL via POST, but the URL doesn't end in a slash and you have APPEND_SLASH set. Django can't redirect to the slash URL while maintaining POST data. Change your form to point to 127.0.0.1:8003/register/ (note the trailing slash), or set APPEND_SLASH=False in your Django settings.
"POST /register HTTP/1.1" 500 60246
/Users/malenkijkotik/Desktop/progs/rsoi-online-store/online-store-customers/customers_app/requesters/authrequester.py changed, reloading.
Watching for file changes with StatReloader
Internal Server Error: /register/
Traceback (most recent call last):
  File "/Users/malenkijkotik/Desktop/progs/rsoi/env/lib/python3.7/site-packages/django/core/handlers/exception.py", line 34, in inner
    response = get_response(request)
  File "/Users/malenkijkotik/Desktop/progs/rsoi/env/lib/python3.7/site-packages/django/core/handlers/base.py", line 115, in _get_response
    response = self.process_exception_by_middleware(e, request)
  File "/Users/malenkijkotik/Desktop/progs/rsoi/env/lib/python3.7/site-packages/django/core/handlers/base.py", line 113, in _get_response
    response = wrapped_callback(request, *callback_args, **callback_kwargs)
  File "/Users/malenkijkotik/Desktop/progs/rsoi/env/lib/python3.7/site-packages/django/views/decorators/csrf.py", line 54, in wrapped_view
    return view_func(*args, **kwargs)
  File "/Users/malenkijkotik/Desktop/progs/rsoi/env/lib/python3.7/site-packages/django/views/generic/base.py", line 71, in view
    return self.dispatch(request, *args, **kwargs)
  File "/Users/malenkijkotik/Desktop/progs/rsoi/env/lib/python3.7/site-packages/rest_framework/views.py", line 499, in dispatch
    self.response = self.finalize_response(request, response, *args, **kwargs)
  File "/Users/malenkijkotik/Desktop/progs/rsoi/env/lib/python3.7/site-packages/rest_framework/views.py", line 414, in finalize_response
    % type(response)
AssertionError: Expected a `Response`, `HttpResponse` or `HttpStreamingResponse` to be returned from the view, but received a `<class 'tuple'>`
"POST /register/ HTTP/1.1" 500 75576
/Users/malenkijkotik/Desktop/progs/rsoi-online-store/online-store-customers/customers_app/views.py changed, reloading.
Watching for file changes with StatReloader
Internal Server Error: /register/
Traceback (most recent call last):
  File "/Users/malenkijkotik/Desktop/progs/rsoi/env/lib/python3.7/site-packages/django/core/handlers/exception.py", line 34, in inner
    response = get_response(request)
  File "/Users/malenkijkotik/Desktop/progs/rsoi/env/lib/python3.7/site-packages/django/core/handlers/base.py", line 115, in _get_response
    response = self.process_exception_by_middleware(e, request)
  File "/Users/malenkijkotik/Desktop/progs/rsoi/env/lib/python3.7/site-packages/django/core/handlers/base.py", line 113, in _get_response
    response = wrapped_callback(request, *callback_args, **callback_kwargs)
  File "/Users/malenkijkotik/Desktop/progs/rsoi/env/lib/python3.7/site-packages/django/views/decorators/csrf.py", line 54, in wrapped_view
    return view_func(*args, **kwargs)
  File "/Users/malenkijkotik/Desktop/progs/rsoi/env/lib/python3.7/site-packages/django/views/generic/base.py", line 71, in view
    return self.dispatch(request, *args, **kwargs)
  File "/Users/malenkijkotik/Desktop/progs/rsoi/env/lib/python3.7/site-packages/rest_framework/views.py", line 499, in dispatch
    self.response = self.finalize_response(request, response, *args, **kwargs)
  File "/Users/malenkijkotik/Desktop/progs/rsoi/env/lib/python3.7/site-packages/rest_framework/views.py", line 414, in finalize_response
    % type(response)
AssertionError: Expected a `Response`, `HttpResponse` or `HttpStreamingResponse` to be returned from the view, but received a `<class 'str'>`
"POST /register/ HTTP/1.1" 500 75554
/Users/malenkijkotik/Desktop/progs/rsoi-online-store/online-store-customers/customers_app/views.py changed, reloading.
Watching for file changes with StatReloader
Internal Server Error: /register/
Traceback (most recent call last):
  File "/Users/malenkijkotik/Desktop/progs/rsoi/env/lib/python3.7/site-packages/django/core/handlers/exception.py", line 34, in inner
    response = get_response(request)
  File "/Users/malenkijkotik/Desktop/progs/rsoi/env/lib/python3.7/site-packages/django/core/handlers/base.py", line 115, in _get_response
    response = self.process_exception_by_middleware(e, request)
  File "/Users/malenkijkotik/Desktop/progs/rsoi/env/lib/python3.7/site-packages/django/core/handlers/base.py", line 113, in _get_response
    response = wrapped_callback(request, *callback_args, **callback_kwargs)
  File "/Users/malenkijkotik/Desktop/progs/rsoi/env/lib/python3.7/site-packages/django/views/decorators/csrf.py", line 54, in wrapped_view
    return view_func(*args, **kwargs)
  File "/Users/malenkijkotik/Desktop/progs/rsoi/env/lib/python3.7/site-packages/django/views/generic/base.py", line 71, in view
    return self.dispatch(request, *args, **kwargs)
  File "/Users/malenkijkotik/Desktop/progs/rsoi/env/lib/python3.7/site-packages/rest_framework/views.py", line 499, in dispatch
    self.response = self.finalize_response(request, response, *args, **kwargs)
  File "/Users/malenkijkotik/Desktop/progs/rsoi/env/lib/python3.7/site-packages/rest_framework/views.py", line 414, in finalize_response
    % type(response)
AssertionError: Expected a `Response`, `HttpResponse` or `HttpStreamingResponse` to be returned from the view, but received a `<class 'str'>`
"POST /register/ HTTP/1.1" 500 75554
/Users/malenkijkotik/Desktop/progs/rsoi-online-store/online-store-customers/customers_app/views.py changed, reloading.
Watching for file changes with StatReloader
Internal Server Error: /register/
Traceback (most recent call last):
  File "/Users/malenkijkotik/Desktop/progs/rsoi/env/lib/python3.7/site-packages/django/core/handlers/exception.py", line 34, in inner
    response = get_response(request)
  File "/Users/malenkijkotik/Desktop/progs/rsoi/env/lib/python3.7/site-packages/django/core/handlers/base.py", line 115, in _get_response
    response = self.process_exception_by_middleware(e, request)
  File "/Users/malenkijkotik/Desktop/progs/rsoi/env/lib/python3.7/site-packages/django/core/handlers/base.py", line 113, in _get_response
    response = wrapped_callback(request, *callback_args, **callback_kwargs)
  File "/Users/malenkijkotik/Desktop/progs/rsoi/env/lib/python3.7/site-packages/django/views/decorators/csrf.py", line 54, in wrapped_view
    return view_func(*args, **kwargs)
  File "/Users/malenkijkotik/Desktop/progs/rsoi/env/lib/python3.7/site-packages/django/views/generic/base.py", line 71, in view
    return self.dispatch(request, *args, **kwargs)
  File "/Users/malenkijkotik/Desktop/progs/rsoi/env/lib/python3.7/site-packages/rest_framework/views.py", line 499, in dispatch
    self.response = self.finalize_response(request, response, *args, **kwargs)
  File "/Users/malenkijkotik/Desktop/progs/rsoi/env/lib/python3.7/site-packages/rest_framework/views.py", line 414, in finalize_response
    % type(response)
AssertionError: Expected a `Response`, `HttpResponse` or `HttpStreamingResponse` to be returned from the view, but received a `<class 'str'>`
"POST /register/ HTTP/1.1" 500 75554
/Users/malenkijkotik/Desktop/progs/rsoi-online-store/online-store-customers/customers_app/requesters/authrequester.py changed, reloading.
Watching for file changes with StatReloader
Internal Server Error: /register/
Traceback (most recent call last):
  File "/Users/malenkijkotik/Desktop/progs/rsoi/env/lib/python3.7/site-packages/requests/models.py", line 379, in prepare_url
    scheme, auth, host, port, path, query, fragment = parse_url(url)
  File "/Users/malenkijkotik/Desktop/progs/rsoi/env/lib/python3.7/site-packages/urllib3/util/url.py", line 401, in parse_url
    return six.raise_from(LocationParseError(source_url), None)
  File "<string>", line 3, in raise_from
urllib3.exceptions.LocationParseError: Failed to parse: http://127.0.0.1:8004register/

During handling of the above exception, another exception occurred:

Traceback (most recent call last):
  File "/Users/malenkijkotik/Desktop/progs/rsoi/env/lib/python3.7/site-packages/django/core/handlers/exception.py", line 34, in inner
    response = get_response(request)
  File "/Users/malenkijkotik/Desktop/progs/rsoi/env/lib/python3.7/site-packages/django/core/handlers/base.py", line 115, in _get_response
    response = self.process_exception_by_middleware(e, request)
  File "/Users/malenkijkotik/Desktop/progs/rsoi/env/lib/python3.7/site-packages/django/core/handlers/base.py", line 113, in _get_response
    response = wrapped_callback(request, *callback_args, **callback_kwargs)
  File "/Users/malenkijkotik/Desktop/progs/rsoi/env/lib/python3.7/site-packages/django/views/decorators/csrf.py", line 54, in wrapped_view
    return view_func(*args, **kwargs)
  File "/Users/malenkijkotik/Desktop/progs/rsoi/env/lib/python3.7/site-packages/django/views/generic/base.py", line 71, in view
    return self.dispatch(request, *args, **kwargs)
  File "/Users/malenkijkotik/Desktop/progs/rsoi/env/lib/python3.7/site-packages/rest_framework/views.py", line 497, in dispatch
    response = self.handle_exception(exc)
  File "/Users/malenkijkotik/Desktop/progs/rsoi/env/lib/python3.7/site-packages/rest_framework/views.py", line 457, in handle_exception
    self.raise_uncaught_exception(exc)
  File "/Users/malenkijkotik/Desktop/progs/rsoi/env/lib/python3.7/site-packages/rest_framework/views.py", line 468, in raise_uncaught_exception
    raise exc
  File "/Users/malenkijkotik/Desktop/progs/rsoi/env/lib/python3.7/site-packages/rest_framework/views.py", line 494, in dispatch
    response = handler(request, *args, **kwargs)
  File "/Users/malenkijkotik/Desktop/progs/rsoi-online-store/online-store-customers/customers_app/views.py", line 85, in post
    response, status_code = AuthRequester().register(request.data['username'], request.data['password'])
  File "/Users/malenkijkotik/Desktop/progs/rsoi-online-store/online-store-customers/customers_app/requesters/authrequester.py", line 22, in register
    response = self.post_request(self.AUTH_HOST + 'register/', data=data)
  File "/Users/malenkijkotik/Desktop/progs/rsoi-online-store/online-store-customers/customers_app/requesters/requester.py", line 19, in post_request
    response = requests.post(url=url, json=data, headers=headers)
  File "/Users/malenkijkotik/Desktop/progs/rsoi/env/lib/python3.7/site-packages/requests/api.py", line 116, in post
    return request('post', url, data=data, json=json, **kwargs)
  File "/Users/malenkijkotik/Desktop/progs/rsoi/env/lib/python3.7/site-packages/requests/api.py", line 60, in request
    return session.request(method=method, url=url, **kwargs)
  File "/Users/malenkijkotik/Desktop/progs/rsoi/env/lib/python3.7/site-packages/requests/sessions.py", line 519, in request
    prep = self.prepare_request(req)
  File "/Users/malenkijkotik/Desktop/progs/rsoi/env/lib/python3.7/site-packages/requests/sessions.py", line 462, in prepare_request
    hooks=merge_hooks(request.hooks, self.hooks),
  File "/Users/malenkijkotik/Desktop/progs/rsoi/env/lib/python3.7/site-packages/requests/models.py", line 313, in prepare
    self.prepare_url(url, params)
  File "/Users/malenkijkotik/Desktop/progs/rsoi/env/lib/python3.7/site-packages/requests/models.py", line 381, in prepare_url
    raise InvalidURL(*e.args)
requests.exceptions.InvalidURL: Failed to parse: http://127.0.0.1:8004register/
"POST /register/ HTTP/1.1" 500 17441
/Users/malenkijkotik/Desktop/progs/rsoi-online-store/online-store-customers/customers_app/requesters/authrequester.py changed, reloading.
Watching for file changes with StatReloader
Internal Server Error: /register/
Traceback (most recent call last):
  File "/Users/malenkijkotik/Desktop/progs/rsoi/env/lib/python3.7/site-packages/django/core/handlers/exception.py", line 34, in inner
    response = get_response(request)
  File "/Users/malenkijkotik/Desktop/progs/rsoi/env/lib/python3.7/site-packages/django/core/handlers/base.py", line 115, in _get_response
    response = self.process_exception_by_middleware(e, request)
  File "/Users/malenkijkotik/Desktop/progs/rsoi/env/lib/python3.7/site-packages/django/core/handlers/base.py", line 113, in _get_response
    response = wrapped_callback(request, *callback_args, **callback_kwargs)
  File "/Users/malenkijkotik/Desktop/progs/rsoi/env/lib/python3.7/site-packages/django/views/decorators/csrf.py", line 54, in wrapped_view
    return view_func(*args, **kwargs)
  File "/Users/malenkijkotik/Desktop/progs/rsoi/env/lib/python3.7/site-packages/django/views/generic/base.py", line 71, in view
    return self.dispatch(request, *args, **kwargs)
  File "/Users/malenkijkotik/Desktop/progs/rsoi/env/lib/python3.7/site-packages/rest_framework/views.py", line 497, in dispatch
    response = self.handle_exception(exc)
  File "/Users/malenkijkotik/Desktop/progs/rsoi/env/lib/python3.7/site-packages/rest_framework/views.py", line 457, in handle_exception
    self.raise_uncaught_exception(exc)
  File "/Users/malenkijkotik/Desktop/progs/rsoi/env/lib/python3.7/site-packages/rest_framework/views.py", line 468, in raise_uncaught_exception
    raise exc
  File "/Users/malenkijkotik/Desktop/progs/rsoi/env/lib/python3.7/site-packages/rest_framework/views.py", line 494, in dispatch
    response = handler(request, *args, **kwargs)
  File "/Users/malenkijkotik/Desktop/progs/rsoi-online-store/online-store-customers/customers_app/views.py", line 92, in post
    user_info, user_status_code = AuthRequester().get_user_info(data_from_response['access'])
  File "/Users/malenkijkotik/Desktop/progs/rsoi-online-store/online-store-customers/customers_app/requesters/authrequester.py", line 12, in get_user_info
    token = self.get_token_from_request(request)
  File "/Users/malenkijkotik/Desktop/progs/rsoi-online-store/online-store-customers/customers_app/requesters/requester.py", line 46, in get_token_from_request
    token = request.META['HTTP_AUTHORIZATION']
AttributeError: 'str' object has no attribute 'META'
"POST /register/ HTTP/1.1" 500 15447
/Users/malenkijkotik/Desktop/progs/rsoi-online-store/online-store-customers/customers_app/views.py changed, reloading.
Watching for file changes with StatReloader
Internal Server Error: /register/
Traceback (most recent call last):
  File "/Users/malenkijkotik/Desktop/progs/rsoi/env/lib/python3.7/site-packages/django/core/handlers/exception.py", line 34, in inner
    response = get_response(request)
  File "/Users/malenkijkotik/Desktop/progs/rsoi/env/lib/python3.7/site-packages/django/core/handlers/base.py", line 115, in _get_response
    response = self.process_exception_by_middleware(e, request)
  File "/Users/malenkijkotik/Desktop/progs/rsoi/env/lib/python3.7/site-packages/django/core/handlers/base.py", line 113, in _get_response
    response = wrapped_callback(request, *callback_args, **callback_kwargs)
  File "/Users/malenkijkotik/Desktop/progs/rsoi/env/lib/python3.7/site-packages/django/views/decorators/csrf.py", line 54, in wrapped_view
    return view_func(*args, **kwargs)
  File "/Users/malenkijkotik/Desktop/progs/rsoi/env/lib/python3.7/site-packages/django/views/generic/base.py", line 71, in view
    return self.dispatch(request, *args, **kwargs)
  File "/Users/malenkijkotik/Desktop/progs/rsoi/env/lib/python3.7/site-packages/rest_framework/views.py", line 499, in dispatch
    self.response = self.finalize_response(request, response, *args, **kwargs)
  File "/Users/malenkijkotik/Desktop/progs/rsoi/env/lib/python3.7/site-packages/rest_framework/views.py", line 414, in finalize_response
    % type(response)
AssertionError: Expected a `Response`, `HttpResponse` or `HttpStreamingResponse` to be returned from the view, but received a `<class 'requests.models.Response'>`
"POST /register/ HTTP/1.1" 500 75570
Internal Server Error: /register/
Traceback (most recent call last):
  File "/Users/malenkijkotik/Desktop/progs/rsoi/env/lib/python3.7/site-packages/django/core/handlers/exception.py", line 34, in inner
    response = get_response(request)
  File "/Users/malenkijkotik/Desktop/progs/rsoi/env/lib/python3.7/site-packages/django/core/handlers/base.py", line 115, in _get_response
    response = self.process_exception_by_middleware(e, request)
  File "/Users/malenkijkotik/Desktop/progs/rsoi/env/lib/python3.7/site-packages/django/core/handlers/base.py", line 113, in _get_response
    response = wrapped_callback(request, *callback_args, **callback_kwargs)
  File "/Users/malenkijkotik/Desktop/progs/rsoi/env/lib/python3.7/site-packages/django/views/decorators/csrf.py", line 54, in wrapped_view
    return view_func(*args, **kwargs)
  File "/Users/malenkijkotik/Desktop/progs/rsoi/env/lib/python3.7/site-packages/django/views/generic/base.py", line 71, in view
    return self.dispatch(request, *args, **kwargs)
  File "/Users/malenkijkotik/Desktop/progs/rsoi/env/lib/python3.7/site-packages/rest_framework/views.py", line 497, in dispatch
    response = self.handle_exception(exc)
  File "/Users/malenkijkotik/Desktop/progs/rsoi/env/lib/python3.7/site-packages/rest_framework/views.py", line 457, in handle_exception
    self.raise_uncaught_exception(exc)
  File "/Users/malenkijkotik/Desktop/progs/rsoi/env/lib/python3.7/site-packages/rest_framework/views.py", line 468, in raise_uncaught_exception
    raise exc
  File "/Users/malenkijkotik/Desktop/progs/rsoi/env/lib/python3.7/site-packages/rest_framework/views.py", line 494, in dispatch
    response = handler(request, *args, **kwargs)
  File "/Users/malenkijkotik/Desktop/progs/rsoi-online-store/online-store-customers/customers_app/views.py", line 93, in post
    user_info, user_status_code = AuthRequester().get_user_info(data_from_response['access'])
  File "/Users/malenkijkotik/Desktop/progs/rsoi-online-store/online-store-customers/customers_app/requesters/authrequester.py", line 12, in get_user_info
    token = self.get_token_from_request(request)
  File "/Users/malenkijkotik/Desktop/progs/rsoi-online-store/online-store-customers/customers_app/requesters/requester.py", line 46, in get_token_from_request
    token = request.META['HTTP_AUTHORIZATION']
AttributeError: 'str' object has no attribute 'META'
"POST /register/ HTTP/1.1" 500 15447
/Users/malenkijkotik/Desktop/progs/rsoi-online-store/online-store-customers/customers_app/requesters/authrequester.py changed, reloading.
Watching for file changes with StatReloader
/Users/malenkijkotik/Desktop/progs/rsoi-online-store/online-store-customers/customers_app/views.py changed, reloading.
Watching for file changes with StatReloader
Internal Server Error: /register/
Traceback (most recent call last):
  File "/Users/malenkijkotik/Desktop/progs/rsoi/env/lib/python3.7/site-packages/django/core/handlers/exception.py", line 34, in inner
    response = get_response(request)
  File "/Users/malenkijkotik/Desktop/progs/rsoi/env/lib/python3.7/site-packages/django/core/handlers/base.py", line 115, in _get_response
    response = self.process_exception_by_middleware(e, request)
  File "/Users/malenkijkotik/Desktop/progs/rsoi/env/lib/python3.7/site-packages/django/core/handlers/base.py", line 113, in _get_response
    response = wrapped_callback(request, *callback_args, **callback_kwargs)
  File "/Users/malenkijkotik/Desktop/progs/rsoi/env/lib/python3.7/site-packages/django/views/decorators/csrf.py", line 54, in wrapped_view
    return view_func(*args, **kwargs)
  File "/Users/malenkijkotik/Desktop/progs/rsoi/env/lib/python3.7/site-packages/django/views/generic/base.py", line 71, in view
    return self.dispatch(request, *args, **kwargs)
  File "/Users/malenkijkotik/Desktop/progs/rsoi/env/lib/python3.7/site-packages/rest_framework/views.py", line 497, in dispatch
    response = self.handle_exception(exc)
  File "/Users/malenkijkotik/Desktop/progs/rsoi/env/lib/python3.7/site-packages/rest_framework/views.py", line 457, in handle_exception
    self.raise_uncaught_exception(exc)
  File "/Users/malenkijkotik/Desktop/progs/rsoi/env/lib/python3.7/site-packages/rest_framework/views.py", line 468, in raise_uncaught_exception
    raise exc
  File "/Users/malenkijkotik/Desktop/progs/rsoi/env/lib/python3.7/site-packages/rest_framework/views.py", line 494, in dispatch
    response = handler(request, *args, **kwargs)
  File "/Users/malenkijkotik/Desktop/progs/rsoi-online-store/online-store-customers/customers_app/views.py", line 93, in post
    user_info, user_status_code = AuthRequester().get_user_info(data_from_response['access'])
  File "/Users/malenkijkotik/Desktop/progs/rsoi-online-store/online-store-customers/customers_app/requesters/authrequester.py", line 12, in get_user_info
    token = self.get_token_from_request(request)
  File "/Users/malenkijkotik/Desktop/progs/rsoi-online-store/online-store-customers/customers_app/requesters/requester.py", line 46, in get_token_from_request
    token = request.META['HTTP_AUTHORIZATION']
AttributeError: 'str' object has no attribute 'META'
"POST /register/ HTTP/1.1" 500 15447
/Users/malenkijkotik/Desktop/progs/rsoi-online-store/online-store-customers/customers_app/views.py changed, reloading.
Watching for file changes with StatReloader
Internal Server Error: /register/
Traceback (most recent call last):
  File "/Users/malenkijkotik/Desktop/progs/rsoi/env/lib/python3.7/site-packages/django/core/handlers/exception.py", line 34, in inner
    response = get_response(request)
  File "/Users/malenkijkotik/Desktop/progs/rsoi/env/lib/python3.7/site-packages/django/core/handlers/base.py", line 115, in _get_response
    response = self.process_exception_by_middleware(e, request)
  File "/Users/malenkijkotik/Desktop/progs/rsoi/env/lib/python3.7/site-packages/django/core/handlers/base.py", line 113, in _get_response
    response = wrapped_callback(request, *callback_args, **callback_kwargs)
  File "/Users/malenkijkotik/Desktop/progs/rsoi/env/lib/python3.7/site-packages/django/views/decorators/csrf.py", line 54, in wrapped_view
    return view_func(*args, **kwargs)
  File "/Users/malenkijkotik/Desktop/progs/rsoi/env/lib/python3.7/site-packages/django/views/generic/base.py", line 71, in view
    return self.dispatch(request, *args, **kwargs)
  File "/Users/malenkijkotik/Desktop/progs/rsoi/env/lib/python3.7/site-packages/rest_framework/views.py", line 497, in dispatch
    response = self.handle_exception(exc)
  File "/Users/malenkijkotik/Desktop/progs/rsoi/env/lib/python3.7/site-packages/rest_framework/views.py", line 457, in handle_exception
    self.raise_uncaught_exception(exc)
  File "/Users/malenkijkotik/Desktop/progs/rsoi/env/lib/python3.7/site-packages/rest_framework/views.py", line 468, in raise_uncaught_exception
    raise exc
  File "/Users/malenkijkotik/Desktop/progs/rsoi/env/lib/python3.7/site-packages/rest_framework/views.py", line 494, in dispatch
    response = handler(request, *args, **kwargs)
  File "/Users/malenkijkotik/Desktop/progs/rsoi-online-store/online-store-customers/customers_app/views.py", line 92, in post
    print(response.META)
AttributeError: 'Response' object has no attribute 'META'
"POST /register/ HTTP/1.1" 500 14986
Watching for file changes with StatReloader
Internal Server Error: /register/
Traceback (most recent call last):
  File "/Users/malenkijkotik/Desktop/progs/rsoi/env/lib/python3.7/site-packages/django/core/handlers/exception.py", line 34, in inner
    response = get_response(request)
  File "/Users/malenkijkotik/Desktop/progs/rsoi/env/lib/python3.7/site-packages/django/core/handlers/base.py", line 115, in _get_response
    response = self.process_exception_by_middleware(e, request)
  File "/Users/malenkijkotik/Desktop/progs/rsoi/env/lib/python3.7/site-packages/django/core/handlers/base.py", line 113, in _get_response
    response = wrapped_callback(request, *callback_args, **callback_kwargs)
  File "/Users/malenkijkotik/Desktop/progs/rsoi/env/lib/python3.7/site-packages/django/views/decorators/csrf.py", line 54, in wrapped_view
    return view_func(*args, **kwargs)
  File "/Users/malenkijkotik/Desktop/progs/rsoi/env/lib/python3.7/site-packages/django/views/generic/base.py", line 71, in view
    return self.dispatch(request, *args, **kwargs)
  File "/Users/malenkijkotik/Desktop/progs/rsoi/env/lib/python3.7/site-packages/rest_framework/views.py", line 497, in dispatch
    response = self.handle_exception(exc)
  File "/Users/malenkijkotik/Desktop/progs/rsoi/env/lib/python3.7/site-packages/rest_framework/views.py", line 457, in handle_exception
    self.raise_uncaught_exception(exc)
  File "/Users/malenkijkotik/Desktop/progs/rsoi/env/lib/python3.7/site-packages/rest_framework/views.py", line 468, in raise_uncaught_exception
    raise exc
  File "/Users/malenkijkotik/Desktop/progs/rsoi/env/lib/python3.7/site-packages/rest_framework/views.py", line 494, in dispatch
    response = handler(request, *args, **kwargs)
  File "/Users/malenkijkotik/Desktop/progs/rsoi-online-store/online-store-customers/customers_app/views.py", line 93, in post
    user_info, user_status_code = AuthRequester().get_user_info(data_from_response['access'])
  File "/Users/malenkijkotik/Desktop/progs/rsoi-online-store/online-store-customers/customers_app/requesters/authrequester.py", line 12, in get_user_info
    token = self.get_token_from_request(request)
  File "/Users/malenkijkotik/Desktop/progs/rsoi-online-store/online-store-customers/customers_app/requesters/requester.py", line 46, in get_token_from_request
    token = request.META['HTTP_AUTHORIZATION']
AttributeError: 'str' object has no attribute 'META'
"POST /register/ HTTP/1.1" 500 15447
/Users/malenkijkotik/Desktop/progs/rsoi-online-store/online-store-customers/customers_app/requesters/authrequester.py changed, reloading.
Watching for file changes with StatReloader
/Users/malenkijkotik/Desktop/progs/rsoi-online-store/online-store-customers/customers_app/requesters/authrequester.py changed, reloading.
Watching for file changes with StatReloader
/Users/malenkijkotik/Desktop/progs/rsoi-online-store/online-store-customers/customers_app/requesters/authrequester.py changed, reloading.
Watching for file changes with StatReloader
/Users/malenkijkotik/Desktop/progs/rsoi-online-store/online-store-customers/customers_app/requesters/authrequester.py changed, reloading.
Watching for file changes with StatReloader
/Users/malenkijkotik/Desktop/progs/rsoi-online-store/online-store-customers/customers_app/requesters/authrequester.py changed, reloading.
Watching for file changes with StatReloader
/Users/malenkijkotik/Desktop/progs/rsoi-online-store/online-store-customers/customers_app/requesters/authrequester.py changed, reloading.
Watching for file changes with StatReloader
/Users/malenkijkotik/Desktop/progs/rsoi-online-store/online-store-customers/customers_app/requesters/authrequester.py changed, reloading.
Watching for file changes with StatReloader
/Users/malenkijkotik/Desktop/progs/rsoi-online-store/online-store-customers/customers_app/requesters/authrequester.py changed, reloading.
Watching for file changes with StatReloader
/Users/malenkijkotik/Desktop/progs/rsoi-online-store/online-store-customers/customers_app/requesters/authrequester.py changed, reloading.
Watching for file changes with StatReloader
/Users/malenkijkotik/Desktop/progs/rsoi-online-store/online-store-customers/customers_app/requesters/authrequester.py changed, reloading.
Watching for file changes with StatReloader
/Users/malenkijkotik/Desktop/progs/rsoi-online-store/online-store-customers/customers_app/requesters/authrequester.py changed, reloading.
Watching for file changes with StatReloader
/Users/malenkijkotik/Desktop/progs/rsoi-online-store/online-store-customers/customers_app/requesters/authrequester.py changed, reloading.
Watching for file changes with StatReloader
Internal Server Error: /register/
Traceback (most recent call last):
  File "/Users/malenkijkotik/Desktop/progs/rsoi/env/lib/python3.7/site-packages/django/core/handlers/exception.py", line 34, in inner
    response = get_response(request)
  File "/Users/malenkijkotik/Desktop/progs/rsoi/env/lib/python3.7/site-packages/django/core/handlers/base.py", line 115, in _get_response
    response = self.process_exception_by_middleware(e, request)
  File "/Users/malenkijkotik/Desktop/progs/rsoi/env/lib/python3.7/site-packages/django/core/handlers/base.py", line 113, in _get_response
    response = wrapped_callback(request, *callback_args, **callback_kwargs)
  File "/Users/malenkijkotik/Desktop/progs/rsoi/env/lib/python3.7/site-packages/django/views/decorators/csrf.py", line 54, in wrapped_view
    return view_func(*args, **kwargs)
  File "/Users/malenkijkotik/Desktop/progs/rsoi/env/lib/python3.7/site-packages/django/views/generic/base.py", line 71, in view
    return self.dispatch(request, *args, **kwargs)
  File "/Users/malenkijkotik/Desktop/progs/rsoi/env/lib/python3.7/site-packages/rest_framework/views.py", line 497, in dispatch
    response = self.handle_exception(exc)
  File "/Users/malenkijkotik/Desktop/progs/rsoi/env/lib/python3.7/site-packages/rest_framework/views.py", line 457, in handle_exception
    self.raise_uncaught_exception(exc)
  File "/Users/malenkijkotik/Desktop/progs/rsoi/env/lib/python3.7/site-packages/rest_framework/views.py", line 468, in raise_uncaught_exception
    raise exc
  File "/Users/malenkijkotik/Desktop/progs/rsoi/env/lib/python3.7/site-packages/rest_framework/views.py", line 494, in dispatch
    response = handler(request, *args, **kwargs)
  File "/Users/malenkijkotik/Desktop/progs/rsoi-online-store/online-store-customers/customers_app/views.py", line 93, in post
    user_info, user_status_code = AuthRequester().get_user_info(data_from_response['access'])
  File "/Users/malenkijkotik/Desktop/progs/rsoi-online-store/online-store-customers/customers_app/requesters/authrequester.py", line 13, in get_user_info
    response = self.get('user_info/', headers=auth_header)
AttributeError: 'AuthRequester' object has no attribute 'get'
"POST /register/ HTTP/1.1" 500 15275
/Users/malenkijkotik/Desktop/progs/rsoi-online-store/online-store-customers/customers_app/requesters/authrequester.py changed, reloading.
Watching for file changes with StatReloader
Internal Server Error: /register/
Traceback (most recent call last):
  File "/Users/malenkijkotik/Desktop/progs/rsoi/env/lib/python3.7/site-packages/django/core/handlers/exception.py", line 34, in inner
    response = get_response(request)
  File "/Users/malenkijkotik/Desktop/progs/rsoi/env/lib/python3.7/site-packages/django/core/handlers/base.py", line 115, in _get_response
    response = self.process_exception_by_middleware(e, request)
  File "/Users/malenkijkotik/Desktop/progs/rsoi/env/lib/python3.7/site-packages/django/core/handlers/base.py", line 113, in _get_response
    response = wrapped_callback(request, *callback_args, **callback_kwargs)
  File "/Users/malenkijkotik/Desktop/progs/rsoi/env/lib/python3.7/site-packages/django/views/decorators/csrf.py", line 54, in wrapped_view
    return view_func(*args, **kwargs)
  File "/Users/malenkijkotik/Desktop/progs/rsoi/env/lib/python3.7/site-packages/django/views/generic/base.py", line 71, in view
    return self.dispatch(request, *args, **kwargs)
  File "/Users/malenkijkotik/Desktop/progs/rsoi/env/lib/python3.7/site-packages/rest_framework/views.py", line 499, in dispatch
    self.response = self.finalize_response(request, response, *args, **kwargs)
  File "/Users/malenkijkotik/Desktop/progs/rsoi/env/lib/python3.7/site-packages/rest_framework/views.py", line 414, in finalize_response
    % type(response)
AssertionError: Expected a `Response`, `HttpResponse` or `HttpStreamingResponse` to be returned from the view, but received a `<class 'requests.models.Response'>`
"POST /register/ HTTP/1.1" 500 75570
Internal Server Error: /register/
Traceback (most recent call last):
  File "/Users/malenkijkotik/Desktop/progs/rsoi/env/lib/python3.7/site-packages/django/core/handlers/exception.py", line 34, in inner
    response = get_response(request)
  File "/Users/malenkijkotik/Desktop/progs/rsoi/env/lib/python3.7/site-packages/django/core/handlers/base.py", line 115, in _get_response
    response = self.process_exception_by_middleware(e, request)
  File "/Users/malenkijkotik/Desktop/progs/rsoi/env/lib/python3.7/site-packages/django/core/handlers/base.py", line 113, in _get_response
    response = wrapped_callback(request, *callback_args, **callback_kwargs)
  File "/Users/malenkijkotik/Desktop/progs/rsoi/env/lib/python3.7/site-packages/django/views/decorators/csrf.py", line 54, in wrapped_view
    return view_func(*args, **kwargs)
  File "/Users/malenkijkotik/Desktop/progs/rsoi/env/lib/python3.7/site-packages/django/views/generic/base.py", line 71, in view
    return self.dispatch(request, *args, **kwargs)
  File "/Users/malenkijkotik/Desktop/progs/rsoi/env/lib/python3.7/site-packages/rest_framework/views.py", line 497, in dispatch
    response = self.handle_exception(exc)
  File "/Users/malenkijkotik/Desktop/progs/rsoi/env/lib/python3.7/site-packages/rest_framework/views.py", line 457, in handle_exception
    self.raise_uncaught_exception(exc)
  File "/Users/malenkijkotik/Desktop/progs/rsoi/env/lib/python3.7/site-packages/rest_framework/views.py", line 468, in raise_uncaught_exception
    raise exc
  File "/Users/malenkijkotik/Desktop/progs/rsoi/env/lib/python3.7/site-packages/rest_framework/views.py", line 494, in dispatch
    response = handler(request, *args, **kwargs)
  File "/Users/malenkijkotik/Desktop/progs/rsoi-online-store/online-store-customers/customers_app/views.py", line 93, in post
    user_info, user_status_code = AuthRequester().get_user_info(data_from_response['access'])
  File "/Users/malenkijkotik/Desktop/progs/rsoi-online-store/online-store-customers/customers_app/requesters/authrequester.py", line 13, in get_user_info
    response = self.get_request('user_info/', headers=auth_header)
  File "/Users/malenkijkotik/Desktop/progs/rsoi-online-store/online-store-customers/customers_app/requesters/requester.py", line 12, in get_request
    response = requests.get(url, headers=headers)
  File "/Users/malenkijkotik/Desktop/progs/rsoi/env/lib/python3.7/site-packages/requests/api.py", line 75, in get
    return request('get', url, params=params, **kwargs)
  File "/Users/malenkijkotik/Desktop/progs/rsoi/env/lib/python3.7/site-packages/requests/api.py", line 60, in request
    return session.request(method=method, url=url, **kwargs)
  File "/Users/malenkijkotik/Desktop/progs/rsoi/env/lib/python3.7/site-packages/requests/sessions.py", line 519, in request
    prep = self.prepare_request(req)
  File "/Users/malenkijkotik/Desktop/progs/rsoi/env/lib/python3.7/site-packages/requests/sessions.py", line 462, in prepare_request
    hooks=merge_hooks(request.hooks, self.hooks),
  File "/Users/malenkijkotik/Desktop/progs/rsoi/env/lib/python3.7/site-packages/requests/models.py", line 313, in prepare
    self.prepare_url(url, params)
  File "/Users/malenkijkotik/Desktop/progs/rsoi/env/lib/python3.7/site-packages/requests/models.py", line 387, in prepare_url
    raise MissingSchema(error)
requests.exceptions.MissingSchema: Invalid URL 'user_info/': No schema supplied. Perhaps you meant http://user_info/?
"POST /register/ HTTP/1.1" 500 16550
/Users/malenkijkotik/Desktop/progs/rsoi-online-store/online-store-customers/customers_app/requesters/authrequester.py changed, reloading.
Watching for file changes with StatReloader
Internal Server Error: /register/
Traceback (most recent call last):
  File "/Users/malenkijkotik/Desktop/progs/rsoi/env/lib/python3.7/site-packages/django/core/handlers/exception.py", line 34, in inner
    response = get_response(request)
  File "/Users/malenkijkotik/Desktop/progs/rsoi/env/lib/python3.7/site-packages/django/core/handlers/base.py", line 115, in _get_response
    response = self.process_exception_by_middleware(e, request)
  File "/Users/malenkijkotik/Desktop/progs/rsoi/env/lib/python3.7/site-packages/django/core/handlers/base.py", line 113, in _get_response
    response = wrapped_callback(request, *callback_args, **callback_kwargs)
  File "/Users/malenkijkotik/Desktop/progs/rsoi/env/lib/python3.7/site-packages/django/views/decorators/csrf.py", line 54, in wrapped_view
    return view_func(*args, **kwargs)
  File "/Users/malenkijkotik/Desktop/progs/rsoi/env/lib/python3.7/site-packages/django/views/generic/base.py", line 71, in view
    return self.dispatch(request, *args, **kwargs)
  File "/Users/malenkijkotik/Desktop/progs/rsoi/env/lib/python3.7/site-packages/rest_framework/views.py", line 497, in dispatch
    response = self.handle_exception(exc)
  File "/Users/malenkijkotik/Desktop/progs/rsoi/env/lib/python3.7/site-packages/rest_framework/views.py", line 457, in handle_exception
    self.raise_uncaught_exception(exc)
  File "/Users/malenkijkotik/Desktop/progs/rsoi/env/lib/python3.7/site-packages/rest_framework/views.py", line 468, in raise_uncaught_exception
    raise exc
  File "/Users/malenkijkotik/Desktop/progs/rsoi/env/lib/python3.7/site-packages/rest_framework/views.py", line 494, in dispatch
    response = handler(request, *args, **kwargs)
  File "/Users/malenkijkotik/Desktop/progs/rsoi-online-store/online-store-customers/customers_app/views.py", line 95, in post
    customer = Customer.objects.create(user_id=user_info_data['user_id'])
KeyError: 'user_id'
"POST /register/ HTTP/1.1" 500 14959
/Users/malenkijkotik/Desktop/progs/rsoi-online-store/online-store-customers/customers_app/views.py changed, reloading.
Watching for file changes with StatReloader
Internal Server Error: /register/
Traceback (most recent call last):
  File "/Users/malenkijkotik/Desktop/progs/rsoi/env/lib/python3.7/site-packages/django/db/backends/utils.py", line 84, in _execute
    return self.cursor.execute(sql, params)
psycopg2.errors.NotNullViolation: null value in column "user_id" violates not-null constraint
DETAIL:  Failing row contains (, null, null, 22305).


The above exception was the direct cause of the following exception:

Traceback (most recent call last):
  File "/Users/malenkijkotik/Desktop/progs/rsoi/env/lib/python3.7/site-packages/django/core/handlers/exception.py", line 34, in inner
    response = get_response(request)
  File "/Users/malenkijkotik/Desktop/progs/rsoi/env/lib/python3.7/site-packages/django/core/handlers/base.py", line 115, in _get_response
    response = self.process_exception_by_middleware(e, request)
  File "/Users/malenkijkotik/Desktop/progs/rsoi/env/lib/python3.7/site-packages/django/core/handlers/base.py", line 113, in _get_response
    response = wrapped_callback(request, *callback_args, **callback_kwargs)
  File "/Users/malenkijkotik/Desktop/progs/rsoi/env/lib/python3.7/site-packages/django/views/decorators/csrf.py", line 54, in wrapped_view
    return view_func(*args, **kwargs)
  File "/Users/malenkijkotik/Desktop/progs/rsoi/env/lib/python3.7/site-packages/django/views/generic/base.py", line 71, in view
    return self.dispatch(request, *args, **kwargs)
  File "/Users/malenkijkotik/Desktop/progs/rsoi/env/lib/python3.7/site-packages/rest_framework/views.py", line 497, in dispatch
    response = self.handle_exception(exc)
  File "/Users/malenkijkotik/Desktop/progs/rsoi/env/lib/python3.7/site-packages/rest_framework/views.py", line 457, in handle_exception
    self.raise_uncaught_exception(exc)
  File "/Users/malenkijkotik/Desktop/progs/rsoi/env/lib/python3.7/site-packages/rest_framework/views.py", line 468, in raise_uncaught_exception
    raise exc
  File "/Users/malenkijkotik/Desktop/progs/rsoi/env/lib/python3.7/site-packages/rest_framework/views.py", line 494, in dispatch
    response = handler(request, *args, **kwargs)
  File "/Users/malenkijkotik/Desktop/progs/rsoi-online-store/online-store-customers/customers_app/views.py", line 95, in post
    customer = Customer.objects.create(user_id=user_info_data['id'])
  File "/Users/malenkijkotik/Desktop/progs/rsoi/env/lib/python3.7/site-packages/django/db/models/manager.py", line 82, in manager_method
    return getattr(self.get_queryset(), name)(*args, **kwargs)
  File "/Users/malenkijkotik/Desktop/progs/rsoi/env/lib/python3.7/site-packages/django/db/models/query.py", line 422, in create
    obj.save(force_insert=True, using=self.db)
  File "/Users/malenkijkotik/Desktop/progs/rsoi/env/lib/python3.7/site-packages/django/db/models/base.py", line 741, in save
    force_update=force_update, update_fields=update_fields)
  File "/Users/malenkijkotik/Desktop/progs/rsoi/env/lib/python3.7/site-packages/django/db/models/base.py", line 779, in save_base
    force_update, using, update_fields,
  File "/Users/malenkijkotik/Desktop/progs/rsoi/env/lib/python3.7/site-packages/django/db/models/base.py", line 870, in _save_table
    result = self._do_insert(cls._base_manager, using, fields, update_pk, raw)
  File "/Users/malenkijkotik/Desktop/progs/rsoi/env/lib/python3.7/site-packages/django/db/models/base.py", line 908, in _do_insert
    using=using, raw=raw)
  File "/Users/malenkijkotik/Desktop/progs/rsoi/env/lib/python3.7/site-packages/django/db/models/manager.py", line 82, in manager_method
    return getattr(self.get_queryset(), name)(*args, **kwargs)
  File "/Users/malenkijkotik/Desktop/progs/rsoi/env/lib/python3.7/site-packages/django/db/models/query.py", line 1186, in _insert
    return query.get_compiler(using=using).execute_sql(return_id)
  File "/Users/malenkijkotik/Desktop/progs/rsoi/env/lib/python3.7/site-packages/django/db/models/sql/compiler.py", line 1375, in execute_sql
    cursor.execute(sql, params)
  File "/Users/malenkijkotik/Desktop/progs/rsoi/env/lib/python3.7/site-packages/django/db/backends/utils.py", line 99, in execute
    return super().execute(sql, params)
  File "/Users/malenkijkotik/Desktop/progs/rsoi/env/lib/python3.7/site-packages/django/db/backends/utils.py", line 67, in execute
    return self._execute_with_wrappers(sql, params, many=False, executor=self._execute)
  File "/Users/malenkijkotik/Desktop/progs/rsoi/env/lib/python3.7/site-packages/django/db/backends/utils.py", line 76, in _execute_with_wrappers
    return executor(sql, params, many, context)
  File "/Users/malenkijkotik/Desktop/progs/rsoi/env/lib/python3.7/site-packages/django/db/backends/utils.py", line 84, in _execute
    return self.cursor.execute(sql, params)
  File "/Users/malenkijkotik/Desktop/progs/rsoi/env/lib/python3.7/site-packages/django/db/utils.py", line 89, in __exit__
    raise dj_exc_value.with_traceback(traceback) from exc_value
  File "/Users/malenkijkotik/Desktop/progs/rsoi/env/lib/python3.7/site-packages/django/db/backends/utils.py", line 84, in _execute
    return self.cursor.execute(sql, params)
django.db.utils.IntegrityError: null value in column "user_id" violates not-null constraint
DETAIL:  Failing row contains (, null, null, 22305).

"POST /register/ HTTP/1.1" 500 18413
/Users/malenkijkotik/Desktop/progs/rsoi-online-store/online-store-customers/customers_app/views.py changed, reloading.
Watching for file changes with StatReloader
Internal Server Error: /register/
Traceback (most recent call last):
  File "/Users/malenkijkotik/Desktop/progs/rsoi/env/lib/python3.7/site-packages/django/db/backends/utils.py", line 84, in _execute
    return self.cursor.execute(sql, params)
psycopg2.errors.NotNullViolation: null value in column "user_id" violates not-null constraint
DETAIL:  Failing row contains (, null, null, 60519).


The above exception was the direct cause of the following exception:

Traceback (most recent call last):
  File "/Users/malenkijkotik/Desktop/progs/rsoi/env/lib/python3.7/site-packages/django/core/handlers/exception.py", line 34, in inner
    response = get_response(request)
  File "/Users/malenkijkotik/Desktop/progs/rsoi/env/lib/python3.7/site-packages/django/core/handlers/base.py", line 115, in _get_response
    response = self.process_exception_by_middleware(e, request)
  File "/Users/malenkijkotik/Desktop/progs/rsoi/env/lib/python3.7/site-packages/django/core/handlers/base.py", line 113, in _get_response
    response = wrapped_callback(request, *callback_args, **callback_kwargs)
  File "/Users/malenkijkotik/Desktop/progs/rsoi/env/lib/python3.7/site-packages/django/views/decorators/csrf.py", line 54, in wrapped_view
    return view_func(*args, **kwargs)
  File "/Users/malenkijkotik/Desktop/progs/rsoi/env/lib/python3.7/site-packages/django/views/generic/base.py", line 71, in view
    return self.dispatch(request, *args, **kwargs)
  File "/Users/malenkijkotik/Desktop/progs/rsoi/env/lib/python3.7/site-packages/rest_framework/views.py", line 497, in dispatch
    response = self.handle_exception(exc)
  File "/Users/malenkijkotik/Desktop/progs/rsoi/env/lib/python3.7/site-packages/rest_framework/views.py", line 457, in handle_exception
    self.raise_uncaught_exception(exc)
  File "/Users/malenkijkotik/Desktop/progs/rsoi/env/lib/python3.7/site-packages/rest_framework/views.py", line 468, in raise_uncaught_exception
    raise exc
  File "/Users/malenkijkotik/Desktop/progs/rsoi/env/lib/python3.7/site-packages/rest_framework/views.py", line 494, in dispatch
    response = handler(request, *args, **kwargs)
  File "/Users/malenkijkotik/Desktop/progs/rsoi-online-store/online-store-customers/customers_app/views.py", line 96, in post
    customer = Customer.objects.create(user_id=user_info_data['id'])
  File "/Users/malenkijkotik/Desktop/progs/rsoi/env/lib/python3.7/site-packages/django/db/models/manager.py", line 82, in manager_method
    return getattr(self.get_queryset(), name)(*args, **kwargs)
  File "/Users/malenkijkotik/Desktop/progs/rsoi/env/lib/python3.7/site-packages/django/db/models/query.py", line 422, in create
    obj.save(force_insert=True, using=self.db)
  File "/Users/malenkijkotik/Desktop/progs/rsoi/env/lib/python3.7/site-packages/django/db/models/base.py", line 741, in save
    force_update=force_update, update_fields=update_fields)
  File "/Users/malenkijkotik/Desktop/progs/rsoi/env/lib/python3.7/site-packages/django/db/models/base.py", line 779, in save_base
    force_update, using, update_fields,
  File "/Users/malenkijkotik/Desktop/progs/rsoi/env/lib/python3.7/site-packages/django/db/models/base.py", line 870, in _save_table
    result = self._do_insert(cls._base_manager, using, fields, update_pk, raw)
  File "/Users/malenkijkotik/Desktop/progs/rsoi/env/lib/python3.7/site-packages/django/db/models/base.py", line 908, in _do_insert
    using=using, raw=raw)
  File "/Users/malenkijkotik/Desktop/progs/rsoi/env/lib/python3.7/site-packages/django/db/models/manager.py", line 82, in manager_method
    return getattr(self.get_queryset(), name)(*args, **kwargs)
  File "/Users/malenkijkotik/Desktop/progs/rsoi/env/lib/python3.7/site-packages/django/db/models/query.py", line 1186, in _insert
    return query.get_compiler(using=using).execute_sql(return_id)
  File "/Users/malenkijkotik/Desktop/progs/rsoi/env/lib/python3.7/site-packages/django/db/models/sql/compiler.py", line 1375, in execute_sql
    cursor.execute(sql, params)
  File "/Users/malenkijkotik/Desktop/progs/rsoi/env/lib/python3.7/site-packages/django/db/backends/utils.py", line 99, in execute
    return super().execute(sql, params)
  File "/Users/malenkijkotik/Desktop/progs/rsoi/env/lib/python3.7/site-packages/django/db/backends/utils.py", line 67, in execute
    return self._execute_with_wrappers(sql, params, many=False, executor=self._execute)
  File "/Users/malenkijkotik/Desktop/progs/rsoi/env/lib/python3.7/site-packages/django/db/backends/utils.py", line 76, in _execute_with_wrappers
    return executor(sql, params, many, context)
  File "/Users/malenkijkotik/Desktop/progs/rsoi/env/lib/python3.7/site-packages/django/db/backends/utils.py", line 84, in _execute
    return self.cursor.execute(sql, params)
  File "/Users/malenkijkotik/Desktop/progs/rsoi/env/lib/python3.7/site-packages/django/db/utils.py", line 89, in __exit__
    raise dj_exc_value.with_traceback(traceback) from exc_value
  File "/Users/malenkijkotik/Desktop/progs/rsoi/env/lib/python3.7/site-packages/django/db/backends/utils.py", line 84, in _execute
    return self.cursor.execute(sql, params)
django.db.utils.IntegrityError: null value in column "user_id" violates not-null constraint
DETAIL:  Failing row contains (, null, null, 60519).

"POST /register/ HTTP/1.1" 500 18413
/Users/malenkijkotik/Desktop/progs/rsoi-online-store/online-store-customers/customers_app/views.py changed, reloading.
Watching for file changes with StatReloader
Internal Server Error: /register/
Traceback (most recent call last):
  File "/Users/malenkijkotik/Desktop/progs/rsoi/env/lib/python3.7/site-packages/django/core/handlers/exception.py", line 34, in inner
    response = get_response(request)
  File "/Users/malenkijkotik/Desktop/progs/rsoi/env/lib/python3.7/site-packages/django/core/handlers/base.py", line 115, in _get_response
    response = self.process_exception_by_middleware(e, request)
  File "/Users/malenkijkotik/Desktop/progs/rsoi/env/lib/python3.7/site-packages/django/core/handlers/base.py", line 113, in _get_response
    response = wrapped_callback(request, *callback_args, **callback_kwargs)
  File "/Users/malenkijkotik/Desktop/progs/rsoi/env/lib/python3.7/site-packages/django/views/decorators/csrf.py", line 54, in wrapped_view
    return view_func(*args, **kwargs)
  File "/Users/malenkijkotik/Desktop/progs/rsoi/env/lib/python3.7/site-packages/django/views/generic/base.py", line 71, in view
    return self.dispatch(request, *args, **kwargs)
  File "/Users/malenkijkotik/Desktop/progs/rsoi/env/lib/python3.7/site-packages/rest_framework/views.py", line 499, in dispatch
    self.response = self.finalize_response(request, response, *args, **kwargs)
  File "/Users/malenkijkotik/Desktop/progs/rsoi/env/lib/python3.7/site-packages/rest_framework/views.py", line 414, in finalize_response
    % type(response)
AssertionError: Expected a `Response`, `HttpResponse` or `HttpStreamingResponse` to be returned from the view, but received a `<class 'NoneType'>`
"POST /register/ HTTP/1.1" 500 75470
Internal Server Error: /register/
Traceback (most recent call last):
  File "/Users/malenkijkotik/Desktop/progs/rsoi/env/lib/python3.7/site-packages/django/core/handlers/exception.py", line 34, in inner
    response = get_response(request)
  File "/Users/malenkijkotik/Desktop/progs/rsoi/env/lib/python3.7/site-packages/django/core/handlers/base.py", line 115, in _get_response
    response = self.process_exception_by_middleware(e, request)
  File "/Users/malenkijkotik/Desktop/progs/rsoi/env/lib/python3.7/site-packages/django/core/handlers/base.py", line 113, in _get_response
    response = wrapped_callback(request, *callback_args, **callback_kwargs)
  File "/Users/malenkijkotik/Desktop/progs/rsoi/env/lib/python3.7/site-packages/django/views/decorators/csrf.py", line 54, in wrapped_view
    return view_func(*args, **kwargs)
  File "/Users/malenkijkotik/Desktop/progs/rsoi/env/lib/python3.7/site-packages/django/views/generic/base.py", line 71, in view
    return self.dispatch(request, *args, **kwargs)
  File "/Users/malenkijkotik/Desktop/progs/rsoi/env/lib/python3.7/site-packages/rest_framework/views.py", line 499, in dispatch
    self.response = self.finalize_response(request, response, *args, **kwargs)
  File "/Users/malenkijkotik/Desktop/progs/rsoi/env/lib/python3.7/site-packages/rest_framework/views.py", line 414, in finalize_response
    % type(response)
AssertionError: Expected a `Response`, `HttpResponse` or `HttpStreamingResponse` to be returned from the view, but received a `<class 'NoneType'>`
"POST /register/ HTTP/1.1" 500 75470
/Users/malenkijkotik/Desktop/progs/rsoi-online-store/online-store-customers/customers_app/requesters/authrequester.py changed, reloading.
Watching for file changes with StatReloader
Internal Server Error: /register/
Traceback (most recent call last):
  File "/Users/malenkijkotik/Desktop/progs/rsoi/env/lib/python3.7/site-packages/django/core/handlers/exception.py", line 34, in inner
    response = get_response(request)
  File "/Users/malenkijkotik/Desktop/progs/rsoi/env/lib/python3.7/site-packages/django/core/handlers/base.py", line 115, in _get_response
    response = self.process_exception_by_middleware(e, request)
  File "/Users/malenkijkotik/Desktop/progs/rsoi/env/lib/python3.7/site-packages/django/core/handlers/base.py", line 113, in _get_response
    response = wrapped_callback(request, *callback_args, **callback_kwargs)
  File "/Users/malenkijkotik/Desktop/progs/rsoi/env/lib/python3.7/site-packages/django/views/decorators/csrf.py", line 54, in wrapped_view
    return view_func(*args, **kwargs)
  File "/Users/malenkijkotik/Desktop/progs/rsoi/env/lib/python3.7/site-packages/django/views/generic/base.py", line 71, in view
    return self.dispatch(request, *args, **kwargs)
  File "/Users/malenkijkotik/Desktop/progs/rsoi/env/lib/python3.7/site-packages/rest_framework/views.py", line 499, in dispatch
    self.response = self.finalize_response(request, response, *args, **kwargs)
  File "/Users/malenkijkotik/Desktop/progs/rsoi/env/lib/python3.7/site-packages/rest_framework/views.py", line 414, in finalize_response
    % type(response)
AssertionError: Expected a `Response`, `HttpResponse` or `HttpStreamingResponse` to be returned from the view, but received a `<class 'NoneType'>`
"POST /register/ HTTP/1.1" 500 75470
/Users/malenkijkotik/Desktop/progs/rsoi-online-store/online-store-customers/customers_app/requesters/authrequester.py changed, reloading.
Watching for file changes with StatReloader
Internal Server Error: /register/
Traceback (most recent call last):
  File "/Users/malenkijkotik/Desktop/progs/rsoi/env/lib/python3.7/site-packages/django/core/handlers/exception.py", line 34, in inner
    response = get_response(request)
  File "/Users/malenkijkotik/Desktop/progs/rsoi/env/lib/python3.7/site-packages/django/core/handlers/base.py", line 115, in _get_response
    response = self.process_exception_by_middleware(e, request)
  File "/Users/malenkijkotik/Desktop/progs/rsoi/env/lib/python3.7/site-packages/django/core/handlers/base.py", line 113, in _get_response
    response = wrapped_callback(request, *callback_args, **callback_kwargs)
  File "/Users/malenkijkotik/Desktop/progs/rsoi/env/lib/python3.7/site-packages/django/views/decorators/csrf.py", line 54, in wrapped_view
    return view_func(*args, **kwargs)
  File "/Users/malenkijkotik/Desktop/progs/rsoi/env/lib/python3.7/site-packages/django/views/generic/base.py", line 71, in view
    return self.dispatch(request, *args, **kwargs)
  File "/Users/malenkijkotik/Desktop/progs/rsoi/env/lib/python3.7/site-packages/rest_framework/views.py", line 499, in dispatch
    self.response = self.finalize_response(request, response, *args, **kwargs)
  File "/Users/malenkijkotik/Desktop/progs/rsoi/env/lib/python3.7/site-packages/rest_framework/views.py", line 414, in finalize_response
    % type(response)
AssertionError: Expected a `Response`, `HttpResponse` or `HttpStreamingResponse` to be returned from the view, but received a `<class 'requests.models.Response'>`
"POST /register/ HTTP/1.1" 500 75570
Internal Server Error: /register/
Traceback (most recent call last):
  File "/Users/malenkijkotik/Desktop/progs/rsoi/env/lib/python3.7/site-packages/django/core/handlers/exception.py", line 34, in inner
    response = get_response(request)
  File "/Users/malenkijkotik/Desktop/progs/rsoi/env/lib/python3.7/site-packages/django/core/handlers/base.py", line 115, in _get_response
    response = self.process_exception_by_middleware(e, request)
  File "/Users/malenkijkotik/Desktop/progs/rsoi/env/lib/python3.7/site-packages/django/core/handlers/base.py", line 113, in _get_response
    response = wrapped_callback(request, *callback_args, **callback_kwargs)
  File "/Users/malenkijkotik/Desktop/progs/rsoi/env/lib/python3.7/site-packages/django/views/decorators/csrf.py", line 54, in wrapped_view
    return view_func(*args, **kwargs)
  File "/Users/malenkijkotik/Desktop/progs/rsoi/env/lib/python3.7/site-packages/django/views/generic/base.py", line 71, in view
    return self.dispatch(request, *args, **kwargs)
  File "/Users/malenkijkotik/Desktop/progs/rsoi/env/lib/python3.7/site-packages/rest_framework/views.py", line 499, in dispatch
    self.response = self.finalize_response(request, response, *args, **kwargs)
  File "/Users/malenkijkotik/Desktop/progs/rsoi/env/lib/python3.7/site-packages/rest_framework/views.py", line 414, in finalize_response
    % type(response)
AssertionError: Expected a `Response`, `HttpResponse` or `HttpStreamingResponse` to be returned from the view, but received a `<class 'NoneType'>`
"POST /register/ HTTP/1.1" 500 75470
Internal Server Error: /register/
Traceback (most recent call last):
  File "/Users/malenkijkotik/Desktop/progs/rsoi/env/lib/python3.7/site-packages/django/core/handlers/exception.py", line 34, in inner
    response = get_response(request)
  File "/Users/malenkijkotik/Desktop/progs/rsoi/env/lib/python3.7/site-packages/django/core/handlers/base.py", line 115, in _get_response
    response = self.process_exception_by_middleware(e, request)
  File "/Users/malenkijkotik/Desktop/progs/rsoi/env/lib/python3.7/site-packages/django/core/handlers/base.py", line 113, in _get_response
    response = wrapped_callback(request, *callback_args, **callback_kwargs)
  File "/Users/malenkijkotik/Desktop/progs/rsoi/env/lib/python3.7/site-packages/django/views/decorators/csrf.py", line 54, in wrapped_view
    return view_func(*args, **kwargs)
  File "/Users/malenkijkotik/Desktop/progs/rsoi/env/lib/python3.7/site-packages/django/views/generic/base.py", line 71, in view
    return self.dispatch(request, *args, **kwargs)
  File "/Users/malenkijkotik/Desktop/progs/rsoi/env/lib/python3.7/site-packages/rest_framework/views.py", line 499, in dispatch
    self.response = self.finalize_response(request, response, *args, **kwargs)
  File "/Users/malenkijkotik/Desktop/progs/rsoi/env/lib/python3.7/site-packages/rest_framework/views.py", line 414, in finalize_response
    % type(response)
AssertionError: Expected a `Response`, `HttpResponse` or `HttpStreamingResponse` to be returned from the view, but received a `<class 'requests.models.Response'>`
"POST /register/ HTTP/1.1" 500 75570
Internal Server Error: /register/
Traceback (most recent call last):
  File "/Users/malenkijkotik/Desktop/progs/rsoi/env/lib/python3.7/site-packages/django/core/handlers/exception.py", line 34, in inner
    response = get_response(request)
  File "/Users/malenkijkotik/Desktop/progs/rsoi/env/lib/python3.7/site-packages/django/core/handlers/base.py", line 115, in _get_response
    response = self.process_exception_by_middleware(e, request)
  File "/Users/malenkijkotik/Desktop/progs/rsoi/env/lib/python3.7/site-packages/django/core/handlers/base.py", line 113, in _get_response
    response = wrapped_callback(request, *callback_args, **callback_kwargs)
  File "/Users/malenkijkotik/Desktop/progs/rsoi/env/lib/python3.7/site-packages/django/views/decorators/csrf.py", line 54, in wrapped_view
    return view_func(*args, **kwargs)
  File "/Users/malenkijkotik/Desktop/progs/rsoi/env/lib/python3.7/site-packages/django/views/generic/base.py", line 71, in view
    return self.dispatch(request, *args, **kwargs)
  File "/Users/malenkijkotik/Desktop/progs/rsoi/env/lib/python3.7/site-packages/rest_framework/views.py", line 499, in dispatch
    self.response = self.finalize_response(request, response, *args, **kwargs)
  File "/Users/malenkijkotik/Desktop/progs/rsoi/env/lib/python3.7/site-packages/rest_framework/views.py", line 414, in finalize_response
    % type(response)
AssertionError: Expected a `Response`, `HttpResponse` or `HttpStreamingResponse` to be returned from the view, but received a `<class 'requests.models.Response'>`
"POST /register/ HTTP/1.1" 500 75570
Internal Server Error: /register/
Traceback (most recent call last):
  File "/Users/malenkijkotik/Desktop/progs/rsoi/env/lib/python3.7/site-packages/django/core/handlers/exception.py", line 34, in inner
    response = get_response(request)
  File "/Users/malenkijkotik/Desktop/progs/rsoi/env/lib/python3.7/site-packages/django/core/handlers/base.py", line 115, in _get_response
    response = self.process_exception_by_middleware(e, request)
  File "/Users/malenkijkotik/Desktop/progs/rsoi/env/lib/python3.7/site-packages/django/core/handlers/base.py", line 113, in _get_response
    response = wrapped_callback(request, *callback_args, **callback_kwargs)
  File "/Users/malenkijkotik/Desktop/progs/rsoi/env/lib/python3.7/site-packages/django/views/decorators/csrf.py", line 54, in wrapped_view
    return view_func(*args, **kwargs)
  File "/Users/malenkijkotik/Desktop/progs/rsoi/env/lib/python3.7/site-packages/django/views/generic/base.py", line 71, in view
    return self.dispatch(request, *args, **kwargs)
  File "/Users/malenkijkotik/Desktop/progs/rsoi/env/lib/python3.7/site-packages/rest_framework/views.py", line 499, in dispatch
    self.response = self.finalize_response(request, response, *args, **kwargs)
  File "/Users/malenkijkotik/Desktop/progs/rsoi/env/lib/python3.7/site-packages/rest_framework/views.py", line 414, in finalize_response
    % type(response)
AssertionError: Expected a `Response`, `HttpResponse` or `HttpStreamingResponse` to be returned from the view, but received a `<class 'requests.models.Response'>`
"POST /register/ HTTP/1.1" 500 75570
/Users/malenkijkotik/Desktop/progs/rsoi-online-store/online-store-customers/customers/settings.py changed, reloading.
Watching for file changes with StatReloader
Watching for file changes with StatReloader
/Users/malenkijkotik/Desktop/progs/rsoi-online-store/online-store-customers/customers/settings.py changed, reloading.
Watching for file changes with StatReloader
/Users/malenkijkotik/Desktop/progs/rsoi-online-store/online-store-customers/customers/settings.py changed, reloading.
Watching for file changes with StatReloader
Watching for file changes with StatReloader
Internal Server Error: /register/
Traceback (most recent call last):
  File "/Users/malenkijkotik/Desktop/progs/rsoi/env/lib/python3.7/site-packages/django/core/handlers/exception.py", line 34, in inner
    response = get_response(request)
  File "/Users/malenkijkotik/Desktop/progs/rsoi/env/lib/python3.7/site-packages/django/core/handlers/base.py", line 115, in _get_response
    response = self.process_exception_by_middleware(e, request)
  File "/Users/malenkijkotik/Desktop/progs/rsoi/env/lib/python3.7/site-packages/django/core/handlers/base.py", line 113, in _get_response
    response = wrapped_callback(request, *callback_args, **callback_kwargs)
  File "/Users/malenkijkotik/Desktop/progs/rsoi/env/lib/python3.7/site-packages/django/views/decorators/csrf.py", line 54, in wrapped_view
    return view_func(*args, **kwargs)
  File "/Users/malenkijkotik/Desktop/progs/rsoi/env/lib/python3.7/site-packages/django/views/generic/base.py", line 71, in view
    return self.dispatch(request, *args, **kwargs)
  File "/Users/malenkijkotik/Desktop/progs/rsoi/env/lib/python3.7/site-packages/rest_framework/views.py", line 499, in dispatch
    self.response = self.finalize_response(request, response, *args, **kwargs)
  File "/Users/malenkijkotik/Desktop/progs/rsoi/env/lib/python3.7/site-packages/rest_framework/views.py", line 414, in finalize_response
    % type(response)
AssertionError: Expected a `Response`, `HttpResponse` or `HttpStreamingResponse` to be returned from the view, but received a `<class 'requests.models.Response'>`
"POST /register/ HTTP/1.1" 500 76065
Internal Server Error: /register/
Traceback (most recent call last):
  File "/Users/malenkijkotik/Desktop/progs/rsoi/env/lib/python3.7/site-packages/django/core/handlers/exception.py", line 34, in inner
    response = get_response(request)
  File "/Users/malenkijkotik/Desktop/progs/rsoi/env/lib/python3.7/site-packages/django/core/handlers/base.py", line 115, in _get_response
    response = self.process_exception_by_middleware(e, request)
  File "/Users/malenkijkotik/Desktop/progs/rsoi/env/lib/python3.7/site-packages/django/core/handlers/base.py", line 113, in _get_response
    response = wrapped_callback(request, *callback_args, **callback_kwargs)
  File "/Users/malenkijkotik/Desktop/progs/rsoi/env/lib/python3.7/site-packages/django/views/decorators/csrf.py", line 54, in wrapped_view
    return view_func(*args, **kwargs)
  File "/Users/malenkijkotik/Desktop/progs/rsoi/env/lib/python3.7/site-packages/django/views/generic/base.py", line 71, in view
    return self.dispatch(request, *args, **kwargs)
  File "/Users/malenkijkotik/Desktop/progs/rsoi/env/lib/python3.7/site-packages/rest_framework/views.py", line 497, in dispatch
    response = self.handle_exception(exc)
  File "/Users/malenkijkotik/Desktop/progs/rsoi/env/lib/python3.7/site-packages/rest_framework/views.py", line 457, in handle_exception
    self.raise_uncaught_exception(exc)
  File "/Users/malenkijkotik/Desktop/progs/rsoi/env/lib/python3.7/site-packages/rest_framework/views.py", line 468, in raise_uncaught_exception
    raise exc
  File "/Users/malenkijkotik/Desktop/progs/rsoi/env/lib/python3.7/site-packages/rest_framework/views.py", line 494, in dispatch
    response = handler(request, *args, **kwargs)
  File "/Users/malenkijkotik/Desktop/progs/rsoi-online-store/online-store-customers/customers_app/views.py", line 95, in post
    print(f'USER ID {user_info_data["id"]}')
TypeError: string indices must be integers
"POST /register/ HTTP/1.1" 500 15256
Internal Server Error: /register/
Traceback (most recent call last):
  File "/Users/malenkijkotik/Desktop/progs/rsoi/env/lib/python3.7/site-packages/django/core/handlers/exception.py", line 34, in inner
    response = get_response(request)
  File "/Users/malenkijkotik/Desktop/progs/rsoi/env/lib/python3.7/site-packages/django/core/handlers/base.py", line 115, in _get_response
    response = self.process_exception_by_middleware(e, request)
  File "/Users/malenkijkotik/Desktop/progs/rsoi/env/lib/python3.7/site-packages/django/core/handlers/base.py", line 113, in _get_response
    response = wrapped_callback(request, *callback_args, **callback_kwargs)
  File "/Users/malenkijkotik/Desktop/progs/rsoi/env/lib/python3.7/site-packages/django/views/decorators/csrf.py", line 54, in wrapped_view
    return view_func(*args, **kwargs)
  File "/Users/malenkijkotik/Desktop/progs/rsoi/env/lib/python3.7/site-packages/django/views/generic/base.py", line 71, in view
    return self.dispatch(request, *args, **kwargs)
  File "/Users/malenkijkotik/Desktop/progs/rsoi/env/lib/python3.7/site-packages/rest_framework/views.py", line 497, in dispatch
    response = self.handle_exception(exc)
  File "/Users/malenkijkotik/Desktop/progs/rsoi/env/lib/python3.7/site-packages/rest_framework/views.py", line 457, in handle_exception
    self.raise_uncaught_exception(exc)
  File "/Users/malenkijkotik/Desktop/progs/rsoi/env/lib/python3.7/site-packages/rest_framework/views.py", line 468, in raise_uncaught_exception
    raise exc
  File "/Users/malenkijkotik/Desktop/progs/rsoi/env/lib/python3.7/site-packages/rest_framework/views.py", line 494, in dispatch
    response = handler(request, *args, **kwargs)
  File "/Users/malenkijkotik/Desktop/progs/rsoi-online-store/online-store-customers/customers_app/views.py", line 95, in post
    print(f'USER ID {user_info_data["id"]}')
TypeError: string indices must be integers
"POST /register/ HTTP/1.1" 500 15256
Internal Server Error: /register/
Traceback (most recent call last):
  File "/Users/malenkijkotik/Desktop/progs/rsoi/env/lib/python3.7/site-packages/django/core/handlers/exception.py", line 34, in inner
    response = get_response(request)
  File "/Users/malenkijkotik/Desktop/progs/rsoi/env/lib/python3.7/site-packages/django/core/handlers/base.py", line 115, in _get_response
    response = self.process_exception_by_middleware(e, request)
  File "/Users/malenkijkotik/Desktop/progs/rsoi/env/lib/python3.7/site-packages/django/core/handlers/base.py", line 113, in _get_response
    response = wrapped_callback(request, *callback_args, **callback_kwargs)
  File "/Users/malenkijkotik/Desktop/progs/rsoi/env/lib/python3.7/site-packages/django/views/decorators/csrf.py", line 54, in wrapped_view
    return view_func(*args, **kwargs)
  File "/Users/malenkijkotik/Desktop/progs/rsoi/env/lib/python3.7/site-packages/django/views/generic/base.py", line 71, in view
    return self.dispatch(request, *args, **kwargs)
  File "/Users/malenkijkotik/Desktop/progs/rsoi/env/lib/python3.7/site-packages/rest_framework/views.py", line 499, in dispatch
    self.response = self.finalize_response(request, response, *args, **kwargs)
  File "/Users/malenkijkotik/Desktop/progs/rsoi/env/lib/python3.7/site-packages/rest_framework/views.py", line 414, in finalize_response
    % type(response)
AssertionError: Expected a `Response`, `HttpResponse` or `HttpStreamingResponse` to be returned from the view, but received a `<class 'requests.models.Response'>`
"POST /register/ HTTP/1.1" 500 76065
Internal Server Error: /register/
Traceback (most recent call last):
  File "/Users/malenkijkotik/Desktop/progs/rsoi/env/lib/python3.7/site-packages/django/core/handlers/exception.py", line 34, in inner
    response = get_response(request)
  File "/Users/malenkijkotik/Desktop/progs/rsoi/env/lib/python3.7/site-packages/django/core/handlers/base.py", line 115, in _get_response
    response = self.process_exception_by_middleware(e, request)
  File "/Users/malenkijkotik/Desktop/progs/rsoi/env/lib/python3.7/site-packages/django/core/handlers/base.py", line 113, in _get_response
    response = wrapped_callback(request, *callback_args, **callback_kwargs)
  File "/Users/malenkijkotik/Desktop/progs/rsoi/env/lib/python3.7/site-packages/django/views/decorators/csrf.py", line 54, in wrapped_view
    return view_func(*args, **kwargs)
  File "/Users/malenkijkotik/Desktop/progs/rsoi/env/lib/python3.7/site-packages/django/views/generic/base.py", line 71, in view
    return self.dispatch(request, *args, **kwargs)
  File "/Users/malenkijkotik/Desktop/progs/rsoi/env/lib/python3.7/site-packages/rest_framework/views.py", line 499, in dispatch
    self.response = self.finalize_response(request, response, *args, **kwargs)
  File "/Users/malenkijkotik/Desktop/progs/rsoi/env/lib/python3.7/site-packages/rest_framework/views.py", line 414, in finalize_response
    % type(response)
AssertionError: Expected a `Response`, `HttpResponse` or `HttpStreamingResponse` to be returned from the view, but received a `<class 'NoneType'>`
"POST /register/ HTTP/1.1" 500 75965
/Users/malenkijkotik/Desktop/progs/rsoi-online-store/online-store-customers/customers_app/views.py changed, reloading.
Watching for file changes with StatReloader
"POST /register/ HTTP/1.1" 201 625
/Users/malenkijkotik/Desktop/progs/rsoi-online-store/online-store-customers/customers_app/views.py changed, reloading.
Watching for file changes with StatReloader
"GET /all_customers HTTP/1.1" 301 0
"GET /all_customers/ HTTP/1.1" 200 59
"GET /all_customers HTTP/1.1" 301 0
"GET /all_customers/ HTTP/1.1" 200 59
/Users/malenkijkotik/Desktop/progs/rsoi-online-store/online-store-customers/customers_app/permissions.py changed, reloading.
Watching for file changes with StatReloader
"GET /all_customers HTTP/1.1" 301 0
Internal Server Error: /all_customers/
Traceback (most recent call last):
  File "/Users/malenkijkotik/Desktop/progs/rsoi/env/lib/python3.7/site-packages/django/core/handlers/exception.py", line 34, in inner
    response = get_response(request)
  File "/Users/malenkijkotik/Desktop/progs/rsoi/env/lib/python3.7/site-packages/django/core/handlers/base.py", line 115, in _get_response
    response = self.process_exception_by_middleware(e, request)
  File "/Users/malenkijkotik/Desktop/progs/rsoi/env/lib/python3.7/site-packages/django/core/handlers/base.py", line 113, in _get_response
    response = wrapped_callback(request, *callback_args, **callback_kwargs)
  File "/Users/malenkijkotik/Desktop/progs/rsoi/env/lib/python3.7/site-packages/django/views/decorators/csrf.py", line 54, in wrapped_view
    return view_func(*args, **kwargs)
  File "/Users/malenkijkotik/Desktop/progs/rsoi/env/lib/python3.7/site-packages/django/views/generic/base.py", line 71, in view
    return self.dispatch(request, *args, **kwargs)
  File "/Users/malenkijkotik/Desktop/progs/rsoi/env/lib/python3.7/site-packages/rest_framework/views.py", line 497, in dispatch
    response = self.handle_exception(exc)
  File "/Users/malenkijkotik/Desktop/progs/rsoi/env/lib/python3.7/site-packages/rest_framework/views.py", line 457, in handle_exception
    self.raise_uncaught_exception(exc)
  File "/Users/malenkijkotik/Desktop/progs/rsoi/env/lib/python3.7/site-packages/rest_framework/views.py", line 468, in raise_uncaught_exception
    raise exc
  File "/Users/malenkijkotik/Desktop/progs/rsoi/env/lib/python3.7/site-packages/rest_framework/views.py", line 485, in dispatch
    self.initial(request, *args, **kwargs)
  File "/Users/malenkijkotik/Desktop/progs/rsoi/env/lib/python3.7/site-packages/rest_framework/views.py", line 403, in initial
    self.check_permissions(request)
  File "/Users/malenkijkotik/Desktop/progs/rsoi/env/lib/python3.7/site-packages/rest_framework/views.py", line 332, in check_permissions
    if not permission.has_permission(request, self):
  File "/Users/malenkijkotik/Desktop/progs/rsoi-online-store/online-store-customers/customers_app/permissions.py", line 30, in has_permission
    return int(view.kwargs[view.lookup_url_kwarg]) == auth_json['is_superuser']
AttributeError: 'AllCustomersList' object has no attribute 'lookup_url_kwarg'
"GET /all_customers/ HTTP/1.1" 500 15789
/Users/malenkijkotik/Desktop/progs/rsoi-online-store/online-store-customers/customers_app/permissions.py changed, reloading.
Watching for file changes with StatReloader
"GET /all_customers HTTP/1.1" 301 0
"GET /all_customers/ HTTP/1.1" 200 59
/Users/malenkijkotik/Desktop/progs/rsoi-online-store/online-store-customers/customers_app/permissions.py changed, reloading.
Watching for file changes with StatReloader
Watching for file changes with StatReloader
"GET /all_customers HTTP/1.1" 301 0
"GET /all_customers/ HTTP/1.1" 200 59
"GET /23 HTTP/1.1" 301 0
"GET /23/ HTTP/1.1" 200 57
"GET /23/ HTTP/1.1" 200 57
/Users/malenkijkotik/Desktop/progs/rsoi-online-store/online-store-customers/customers_app/permissions.py changed, reloading.
Watching for file changes with StatReloader
"GET /all_customers/ HTTP/1.1" 200 59
/Users/malenkijkotik/Desktop/progs/rsoi-online-store/online-store-customers/customers_app/permissions.py changed, reloading.
Watching for file changes with StatReloader
/Users/malenkijkotik/Desktop/progs/rsoi-online-store/online-store-customers/customers_app/permissions.py changed, reloading.
Watching for file changes with StatReloader
"GET /all_customers/ HTTP/1.1" 200 59
/Users/malenkijkotik/Desktop/progs/rsoi-online-store/online-store-customers/customers_app/permissions.py changed, reloading.
Watching for file changes with StatReloader
Internal Server Error: /all_customers/
Traceback (most recent call last):
  File "/Users/malenkijkotik/Desktop/progs/rsoi/env/lib/python3.7/site-packages/django/core/handlers/exception.py", line 34, in inner
    response = get_response(request)
  File "/Users/malenkijkotik/Desktop/progs/rsoi/env/lib/python3.7/site-packages/django/core/handlers/base.py", line 115, in _get_response
    response = self.process_exception_by_middleware(e, request)
  File "/Users/malenkijkotik/Desktop/progs/rsoi/env/lib/python3.7/site-packages/django/core/handlers/base.py", line 113, in _get_response
    response = wrapped_callback(request, *callback_args, **callback_kwargs)
  File "/Users/malenkijkotik/Desktop/progs/rsoi/env/lib/python3.7/site-packages/django/views/decorators/csrf.py", line 54, in wrapped_view
    return view_func(*args, **kwargs)
  File "/Users/malenkijkotik/Desktop/progs/rsoi/env/lib/python3.7/site-packages/django/views/generic/base.py", line 71, in view
    return self.dispatch(request, *args, **kwargs)
  File "/Users/malenkijkotik/Desktop/progs/rsoi/env/lib/python3.7/site-packages/rest_framework/views.py", line 497, in dispatch
    response = self.handle_exception(exc)
  File "/Users/malenkijkotik/Desktop/progs/rsoi/env/lib/python3.7/site-packages/rest_framework/views.py", line 457, in handle_exception
    self.raise_uncaught_exception(exc)
  File "/Users/malenkijkotik/Desktop/progs/rsoi/env/lib/python3.7/site-packages/rest_framework/views.py", line 468, in raise_uncaught_exception
    raise exc
  File "/Users/malenkijkotik/Desktop/progs/rsoi/env/lib/python3.7/site-packages/rest_framework/views.py", line 485, in dispatch
    self.initial(request, *args, **kwargs)
  File "/Users/malenkijkotik/Desktop/progs/rsoi/env/lib/python3.7/site-packages/rest_framework/views.py", line 403, in initial
    self.check_permissions(request)
  File "/Users/malenkijkotik/Desktop/progs/rsoi/env/lib/python3.7/site-packages/rest_framework/views.py", line 332, in check_permissions
    if not permission.has_permission(request, self):
  File "/Users/malenkijkotik/Desktop/progs/rsoi-online-store/online-store-customers/customers_app/permissions.py", line 32, in has_permission
    print(f'smth : {int(view.kwargs[view.lookup_url_kwarg])}')
AttributeError: 'AllCustomersList' object has no attribute 'lookup_url_kwarg'
"GET /all_customers/ HTTP/1.1" 500 15728
/Users/malenkijkotik/Desktop/progs/rsoi-online-store/online-store-customers/customers_app/permissions.py changed, reloading.
Watching for file changes with StatReloader
/Users/malenkijkotik/Desktop/progs/rsoi-online-store/online-store-customers/customers_app/views.py changed, reloading.
Watching for file changes with StatReloader
Unauthorized: /all_customers/
"GET /all_customers/ HTTP/1.1" 401 58
/Users/malenkijkotik/Desktop/progs/rsoi-online-store/online-store-customers/customers_app/views.py changed, reloading.
Watching for file changes with StatReloader
/Users/malenkijkotik/Desktop/progs/rsoi-online-store/online-store-customers/customers_app/views.py changed, reloading.
Watching for file changes with StatReloader
"GET /all_customers/ HTTP/1.1" 200 59
Not Found: /all_customers/23/
"GET /all_customers/23/ HTTP/1.1" 404 2489
"GET /23/ HTTP/1.1" 200 57
/Users/malenkijkotik/Desktop/progs/rsoi-online-store/online-store-customers/customers_app/permissions.py changed, reloading.
Watching for file changes with StatReloader
Internal Server Error: /23/
Traceback (most recent call last):
  File "/Users/malenkijkotik/Desktop/progs/rsoi/env/lib/python3.7/site-packages/django/core/handlers/exception.py", line 34, in inner
    response = get_response(request)
  File "/Users/malenkijkotik/Desktop/progs/rsoi/env/lib/python3.7/site-packages/django/core/handlers/base.py", line 115, in _get_response
    response = self.process_exception_by_middleware(e, request)
  File "/Users/malenkijkotik/Desktop/progs/rsoi/env/lib/python3.7/site-packages/django/core/handlers/base.py", line 113, in _get_response
    response = wrapped_callback(request, *callback_args, **callback_kwargs)
  File "/Users/malenkijkotik/Desktop/progs/rsoi/env/lib/python3.7/site-packages/django/views/decorators/csrf.py", line 54, in wrapped_view
    return view_func(*args, **kwargs)
  File "/Users/malenkijkotik/Desktop/progs/rsoi/env/lib/python3.7/site-packages/django/views/generic/base.py", line 71, in view
    return self.dispatch(request, *args, **kwargs)
  File "/Users/malenkijkotik/Desktop/progs/rsoi/env/lib/python3.7/site-packages/rest_framework/views.py", line 497, in dispatch
    response = self.handle_exception(exc)
  File "/Users/malenkijkotik/Desktop/progs/rsoi/env/lib/python3.7/site-packages/rest_framework/views.py", line 457, in handle_exception
    self.raise_uncaught_exception(exc)
  File "/Users/malenkijkotik/Desktop/progs/rsoi/env/lib/python3.7/site-packages/rest_framework/views.py", line 468, in raise_uncaught_exception
    raise exc
  File "/Users/malenkijkotik/Desktop/progs/rsoi/env/lib/python3.7/site-packages/rest_framework/views.py", line 485, in dispatch
    self.initial(request, *args, **kwargs)
  File "/Users/malenkijkotik/Desktop/progs/rsoi/env/lib/python3.7/site-packages/rest_framework/views.py", line 403, in initial
    self.check_permissions(request)
  File "/Users/malenkijkotik/Desktop/progs/rsoi/env/lib/python3.7/site-packages/rest_framework/views.py", line 332, in check_permissions
    if not permission.has_permission(request, self):
  File "/Users/malenkijkotik/Desktop/progs/rsoi-online-store/online-store-customers/customers_app/permissions.py", line 21, in has_permission
    return int(view.kwargs[view.lookup_url_kwarg]) == auth_json['id'] or auth_json['is_superuser']
KeyError: 'id'
"GET /23/ HTTP/1.1" 500 15594
/Users/malenkijkotik/Desktop/progs/rsoi-online-store/online-store-customers/customers_app/permissions.py changed, reloading.
Watching for file changes with StatReloader
Internal Server Error: /23/
Traceback (most recent call last):
  File "/Users/malenkijkotik/Desktop/progs/rsoi/env/lib/python3.7/site-packages/django/core/handlers/exception.py", line 34, in inner
    response = get_response(request)
  File "/Users/malenkijkotik/Desktop/progs/rsoi/env/lib/python3.7/site-packages/django/core/handlers/base.py", line 115, in _get_response
    response = self.process_exception_by_middleware(e, request)
  File "/Users/malenkijkotik/Desktop/progs/rsoi/env/lib/python3.7/site-packages/django/core/handlers/base.py", line 113, in _get_response
    response = wrapped_callback(request, *callback_args, **callback_kwargs)
  File "/Users/malenkijkotik/Desktop/progs/rsoi/env/lib/python3.7/site-packages/django/views/decorators/csrf.py", line 54, in wrapped_view
    return view_func(*args, **kwargs)
  File "/Users/malenkijkotik/Desktop/progs/rsoi/env/lib/python3.7/site-packages/django/views/generic/base.py", line 71, in view
    return self.dispatch(request, *args, **kwargs)
  File "/Users/malenkijkotik/Desktop/progs/rsoi/env/lib/python3.7/site-packages/rest_framework/views.py", line 497, in dispatch
    response = self.handle_exception(exc)
  File "/Users/malenkijkotik/Desktop/progs/rsoi/env/lib/python3.7/site-packages/rest_framework/views.py", line 457, in handle_exception
    self.raise_uncaught_exception(exc)
  File "/Users/malenkijkotik/Desktop/progs/rsoi/env/lib/python3.7/site-packages/rest_framework/views.py", line 468, in raise_uncaught_exception
    raise exc
  File "/Users/malenkijkotik/Desktop/progs/rsoi/env/lib/python3.7/site-packages/rest_framework/views.py", line 485, in dispatch
    self.initial(request, *args, **kwargs)
  File "/Users/malenkijkotik/Desktop/progs/rsoi/env/lib/python3.7/site-packages/rest_framework/views.py", line 403, in initial
    self.check_permissions(request)
  File "/Users/malenkijkotik/Desktop/progs/rsoi/env/lib/python3.7/site-packages/rest_framework/views.py", line 332, in check_permissions
    if not permission.has_permission(request, self):
  File "/Users/malenkijkotik/Desktop/progs/rsoi-online-store/online-store-customers/customers_app/permissions.py", line 22, in has_permission
    return int(view.kwargs[view.lookup_url_kwarg]) == auth_json['id'] or auth_json['is_superuser']
KeyError: 'id'
"GET /23/ HTTP/1.1" 500 15594
/Users/malenkijkotik/Desktop/progs/rsoi-online-store/online-store-customers/customers_app/permissions.py changed, reloading.
Watching for file changes with StatReloader
/Users/malenkijkotik/Desktop/progs/rsoi-online-store/online-store-customers/customers_app/permissions.py changed, reloading.
Watching for file changes with StatReloader
/Users/malenkijkotik/Desktop/progs/rsoi-online-store/online-store-customers/customers_app/permissions.py changed, reloading.
Watching for file changes with StatReloader
/Users/malenkijkotik/Desktop/progs/rsoi-online-store/online-store-customers/customers_app/permissions.py changed, reloading.
Watching for file changes with StatReloader
/Users/malenkijkotik/Desktop/progs/rsoi-online-store/online-store-customers/customers_app/permissions.py changed, reloading.
Watching for file changes with StatReloader
"GET /23/ HTTP/1.1" 200 57
/Users/malenkijkotik/Desktop/progs/rsoi-online-store/online-store-customers/customers_app/permissions.py changed, reloading.
Watching for file changes with StatReloader
Internal Server Error: /23/
Traceback (most recent call last):
  File "/Users/malenkijkotik/Desktop/progs/rsoi/env/lib/python3.7/site-packages/django/core/handlers/exception.py", line 34, in inner
    response = get_response(request)
  File "/Users/malenkijkotik/Desktop/progs/rsoi/env/lib/python3.7/site-packages/django/core/handlers/base.py", line 115, in _get_response
    response = self.process_exception_by_middleware(e, request)
  File "/Users/malenkijkotik/Desktop/progs/rsoi/env/lib/python3.7/site-packages/django/core/handlers/base.py", line 113, in _get_response
    response = wrapped_callback(request, *callback_args, **callback_kwargs)
  File "/Users/malenkijkotik/Desktop/progs/rsoi/env/lib/python3.7/site-packages/django/views/decorators/csrf.py", line 54, in wrapped_view
    return view_func(*args, **kwargs)
  File "/Users/malenkijkotik/Desktop/progs/rsoi/env/lib/python3.7/site-packages/django/views/generic/base.py", line 71, in view
    return self.dispatch(request, *args, **kwargs)
  File "/Users/malenkijkotik/Desktop/progs/rsoi/env/lib/python3.7/site-packages/rest_framework/views.py", line 497, in dispatch
    response = self.handle_exception(exc)
  File "/Users/malenkijkotik/Desktop/progs/rsoi/env/lib/python3.7/site-packages/rest_framework/views.py", line 457, in handle_exception
    self.raise_uncaught_exception(exc)
  File "/Users/malenkijkotik/Desktop/progs/rsoi/env/lib/python3.7/site-packages/rest_framework/views.py", line 468, in raise_uncaught_exception
    raise exc
  File "/Users/malenkijkotik/Desktop/progs/rsoi/env/lib/python3.7/site-packages/rest_framework/views.py", line 485, in dispatch
    self.initial(request, *args, **kwargs)
  File "/Users/malenkijkotik/Desktop/progs/rsoi/env/lib/python3.7/site-packages/rest_framework/views.py", line 403, in initial
    self.check_permissions(request)
  File "/Users/malenkijkotik/Desktop/progs/rsoi/env/lib/python3.7/site-packages/rest_framework/views.py", line 332, in check_permissions
    if not permission.has_permission(request, self):
  File "/Users/malenkijkotik/Desktop/progs/rsoi-online-store/online-store-customers/customers_app/permissions.py", line 31, in has_permission
    return int(view.kwargs[view.lookup_url_kwarg]) == auth_json['id'] or auth_json['is_superuser']
KeyError: 'id'
"GET /23/ HTTP/1.1" 500 15598
/Users/malenkijkotik/Desktop/progs/rsoi-online-store/online-store-customers/customers_app/permissions.py changed, reloading.
Watching for file changes with StatReloader
Unauthorized: /23/
"GET /23/ HTTP/1.1" 401 58
/Users/malenkijkotik/Desktop/progs/rsoi-online-store/online-store-customers/customers_app/permissions.py changed, reloading.
Watching for file changes with StatReloader
Bad Request: /register/
"POST /register/ HTTP/1.1" 400 82
"POST /register/ HTTP/1.1" 201 618
/Users/malenkijkotik/Desktop/progs/rsoi-online-store/online-store-customers/customers_app/serializers.py changed, reloading.
Watching for file changes with StatReloader
"POST /register/ HTTP/1.1" 201 621
/Users/malenkijkotik/Desktop/progs/rsoi-online-store/online-store-customers/customers_app/views.py changed, reloading.
Watching for file changes with StatReloader
"POST /register/ HTTP/1.1" 201 649
/Users/malenkijkotik/Desktop/progs/rsoi-online-store/online-store-customers/customers_app/permissions.py changed, reloading.
Watching for file changes with StatReloader
Unauthorized: /26/
"GET /26/ HTTP/1.1" 401 183
Bad Request: /register/
"POST /register/ HTTP/1.1" 400 36
Bad Request: /register/
"POST /register/ HTTP/1.1" 400 36
"POST /register/ HTTP/1.1" 201 621
/Users/malenkijkotik/Desktop/progs/rsoi-online-store/online-store-customers/customers_app/views.py changed, reloading.
Watching for file changes with StatReloader
/Users/malenkijkotik/Desktop/progs/rsoi-online-store/online-store-customers/customers_app/views.py changed, reloading.
Watching for file changes with StatReloader
Watching for file changes with StatReloader
"GET /all_customers HTTP/1.1" 301 0
"GET /all_customers/ HTTP/1.1" 200 326
/Users/malenkijkotik/Desktop/progs/rsoi-online-store/online-store-customers/customers_app/urls.py changed, reloading.
Watching for file changes with StatReloader
"GET /all_customers HTTP/1.1" 301 0
"GET /all_customers/ HTTP/1.1" 200 326
"GET /all_customers/26 HTTP/1.1" 301 0
Internal Server Error: /all_customers/26/
Traceback (most recent call last):
  File "/Users/malenkijkotik/Desktop/progs/rsoi-online-store/online-store-customers/customers_app/requesters/requester.py", line 40, in get_data_from_response
    return response.json()
AttributeError: 'str' object has no attribute 'json'

During handling of the above exception, another exception occurred:

Traceback (most recent call last):
  File "/Users/malenkijkotik/Desktop/progs/rsoi/env/lib/python3.7/site-packages/django/core/handlers/exception.py", line 34, in inner
    response = get_response(request)
  File "/Users/malenkijkotik/Desktop/progs/rsoi/env/lib/python3.7/site-packages/django/core/handlers/base.py", line 115, in _get_response
    response = self.process_exception_by_middleware(e, request)
  File "/Users/malenkijkotik/Desktop/progs/rsoi/env/lib/python3.7/site-packages/django/core/handlers/base.py", line 113, in _get_response
    response = wrapped_callback(request, *callback_args, **callback_kwargs)
  File "/Users/malenkijkotik/Desktop/progs/rsoi/env/lib/python3.7/site-packages/django/views/decorators/csrf.py", line 54, in wrapped_view
    return view_func(*args, **kwargs)
  File "/Users/malenkijkotik/Desktop/progs/rsoi/env/lib/python3.7/site-packages/django/views/generic/base.py", line 71, in view
    return self.dispatch(request, *args, **kwargs)
  File "/Users/malenkijkotik/Desktop/progs/rsoi/env/lib/python3.7/site-packages/rest_framework/views.py", line 497, in dispatch
    response = self.handle_exception(exc)
  File "/Users/malenkijkotik/Desktop/progs/rsoi/env/lib/python3.7/site-packages/rest_framework/views.py", line 457, in handle_exception
    self.raise_uncaught_exception(exc)
  File "/Users/malenkijkotik/Desktop/progs/rsoi/env/lib/python3.7/site-packages/rest_framework/views.py", line 468, in raise_uncaught_exception
    raise exc
  File "/Users/malenkijkotik/Desktop/progs/rsoi/env/lib/python3.7/site-packages/rest_framework/views.py", line 485, in dispatch
    self.initial(request, *args, **kwargs)
  File "/Users/malenkijkotik/Desktop/progs/rsoi/env/lib/python3.7/site-packages/rest_framework/views.py", line 403, in initial
    self.check_permissions(request)
  File "/Users/malenkijkotik/Desktop/progs/rsoi/env/lib/python3.7/site-packages/rest_framework/views.py", line 332, in check_permissions
    if not permission.has_permission(request, self):
  File "/Users/malenkijkotik/Desktop/progs/rsoi-online-store/online-store-customers/customers_app/permissions.py", line 28, in has_permission
    auth_json = r.get_data_from_response(response)
  File "/Users/malenkijkotik/Desktop/progs/rsoi-online-store/online-store-customers/customers_app/requesters/requester.py", line 42, in get_data_from_response
    return response.text
AttributeError: 'str' object has no attribute 'text'
"GET /all_customers/26/ HTTP/1.1" 500 16195
/Users/malenkijkotik/Desktop/progs/rsoi-online-store/online-store-customers/customers_app/views.py changed, reloading.
Watching for file changes with StatReloader
"GET /all_customers/26 HTTP/1.1" 301 0
"GET /all_customers/26/ HTTP/1.1" 200 85
Internal Server Error: /register/
Traceback (most recent call last):
  File "/Users/malenkijkotik/Desktop/progs/rsoi/env/lib/python3.7/site-packages/django/core/handlers/exception.py", line 34, in inner
    response = get_response(request)
  File "/Users/malenkijkotik/Desktop/progs/rsoi/env/lib/python3.7/site-packages/django/core/handlers/base.py", line 115, in _get_response
    response = self.process_exception_by_middleware(e, request)
  File "/Users/malenkijkotik/Desktop/progs/rsoi/env/lib/python3.7/site-packages/django/core/handlers/base.py", line 113, in _get_response
    response = wrapped_callback(request, *callback_args, **callback_kwargs)
  File "/Users/malenkijkotik/Desktop/progs/rsoi/env/lib/python3.7/site-packages/django/views/decorators/csrf.py", line 54, in wrapped_view
    return view_func(*args, **kwargs)
  File "/Users/malenkijkotik/Desktop/progs/rsoi/env/lib/python3.7/site-packages/django/views/generic/base.py", line 71, in view
    return self.dispatch(request, *args, **kwargs)
  File "/Users/malenkijkotik/Desktop/progs/rsoi/env/lib/python3.7/site-packages/rest_framework/views.py", line 499, in dispatch
    self.response = self.finalize_response(request, response, *args, **kwargs)
  File "/Users/malenkijkotik/Desktop/progs/rsoi/env/lib/python3.7/site-packages/rest_framework/views.py", line 414, in finalize_response
    % type(response)
AssertionError: Expected a `Response`, `HttpResponse` or `HttpStreamingResponse` to be returned from the view, but received a `<class 'str'>`
"POST /register/ HTTP/1.1" 500 76676
/Users/malenkijkotik/Desktop/progs/rsoi-online-store/online-store-customers/customers_app/views.py changed, reloading.
Watching for file changes with StatReloader
Internal Server Error: /register/
Traceback (most recent call last):
  File "/Users/malenkijkotik/Desktop/progs/rsoi/env/lib/python3.7/site-packages/django/core/handlers/exception.py", line 34, in inner
    response = get_response(request)
  File "/Users/malenkijkotik/Desktop/progs/rsoi/env/lib/python3.7/site-packages/django/core/handlers/base.py", line 115, in _get_response
    response = self.process_exception_by_middleware(e, request)
  File "/Users/malenkijkotik/Desktop/progs/rsoi/env/lib/python3.7/site-packages/django/core/handlers/base.py", line 113, in _get_response
    response = wrapped_callback(request, *callback_args, **callback_kwargs)
  File "/Users/malenkijkotik/Desktop/progs/rsoi/env/lib/python3.7/site-packages/django/views/decorators/csrf.py", line 54, in wrapped_view
    return view_func(*args, **kwargs)
  File "/Users/malenkijkotik/Desktop/progs/rsoi/env/lib/python3.7/site-packages/django/views/generic/base.py", line 71, in view
    return self.dispatch(request, *args, **kwargs)
  File "/Users/malenkijkotik/Desktop/progs/rsoi/env/lib/python3.7/site-packages/rest_framework/views.py", line 497, in dispatch
    response = self.handle_exception(exc)
  File "/Users/malenkijkotik/Desktop/progs/rsoi/env/lib/python3.7/site-packages/rest_framework/views.py", line 457, in handle_exception
    self.raise_uncaught_exception(exc)
  File "/Users/malenkijkotik/Desktop/progs/rsoi/env/lib/python3.7/site-packages/rest_framework/views.py", line 468, in raise_uncaught_exception
    raise exc
  File "/Users/malenkijkotik/Desktop/progs/rsoi/env/lib/python3.7/site-packages/rest_framework/views.py", line 494, in dispatch
    response = handler(request, *args, **kwargs)
  File "/Users/malenkijkotik/Desktop/progs/rsoi-online-store/online-store-customers/customers_app/views.py", line 91, in post
    return Response(status_code=status.HTTP_500_INTERNAL_SERVER_ERROR)
TypeError: __init__() got an unexpected keyword argument 'status_code'
"POST /register/ HTTP/1.1" 500 15446
/Users/malenkijkotik/Desktop/progs/rsoi-online-store/online-store-customers/customers_app/views.py changed, reloading.
Watching for file changes with StatReloader
Internal Server Error: /register/
"POST /register/ HTTP/1.1" 500 0
Watching for file changes with StatReloader
Internal Server Error: /register/
Traceback (most recent call last):
  File "/Users/malenkijkotik/Desktop/progs/rsoi/env/lib/python3.7/site-packages/django/core/handlers/exception.py", line 34, in inner
    response = get_response(request)
  File "/Users/malenkijkotik/Desktop/progs/rsoi/env/lib/python3.7/site-packages/django/core/handlers/base.py", line 115, in _get_response
    response = self.process_exception_by_middleware(e, request)
  File "/Users/malenkijkotik/Desktop/progs/rsoi/env/lib/python3.7/site-packages/django/core/handlers/base.py", line 113, in _get_response
    response = wrapped_callback(request, *callback_args, **callback_kwargs)
  File "/Users/malenkijkotik/Desktop/progs/rsoi/env/lib/python3.7/site-packages/django/views/decorators/csrf.py", line 54, in wrapped_view
    return view_func(*args, **kwargs)
  File "/Users/malenkijkotik/Desktop/progs/rsoi/env/lib/python3.7/site-packages/django/views/generic/base.py", line 71, in view
    return self.dispatch(request, *args, **kwargs)
  File "/Users/malenkijkotik/Desktop/progs/rsoi/env/lib/python3.7/site-packages/rest_framework/views.py", line 497, in dispatch
    response = self.handle_exception(exc)
  File "/Users/malenkijkotik/Desktop/progs/rsoi/env/lib/python3.7/site-packages/rest_framework/views.py", line 457, in handle_exception
    self.raise_uncaught_exception(exc)
  File "/Users/malenkijkotik/Desktop/progs/rsoi/env/lib/python3.7/site-packages/rest_framework/views.py", line 468, in raise_uncaught_exception
    raise exc
  File "/Users/malenkijkotik/Desktop/progs/rsoi/env/lib/python3.7/site-packages/rest_framework/views.py", line 494, in dispatch
    response = handler(request, *args, **kwargs)
  File "/Users/malenkijkotik/Desktop/progs/rsoi-online-store/online-store-customers/customers_app/views.py", line 88, in post
    response, status_code = AuthRequester().register(request.data['username'], request.data['password'])
  File "/Users/malenkijkotik/Desktop/progs/rsoi-online-store/online-store-customers/customers_app/requesters/authrequester.py", line 22, in register
    response = self.post_request(self.AUTH_HOST + 'register/', data=data)
  File "/Users/malenkijkotik/Desktop/progs/rsoi-online-store/online-store-customers/customers_app/requesters/requester.py", line 19, in post_request
    response = requests.post(url=url, json=data, headers=headers)
  File "/Users/malenkijkotik/Desktop/progs/rsoi/env/lib/python3.7/site-packages/requests/api.py", line 116, in post
    return request('post', url, data=data, json=json, **kwargs)
  File "/Users/malenkijkotik/Desktop/progs/rsoi/env/lib/python3.7/site-packages/requests/api.py", line 60, in request
    return session.request(method=method, url=url, **kwargs)
  File "/Users/malenkijkotik/Desktop/progs/rsoi/env/lib/python3.7/site-packages/requests/sessions.py", line 519, in request
    prep = self.prepare_request(req)
  File "/Users/malenkijkotik/Desktop/progs/rsoi/env/lib/python3.7/site-packages/requests/sessions.py", line 462, in prepare_request
    hooks=merge_hooks(request.hooks, self.hooks),
  File "/Users/malenkijkotik/Desktop/progs/rsoi/env/lib/python3.7/site-packages/requests/models.py", line 313, in prepare
    self.prepare_url(url, params)
  File "/Users/malenkijkotik/Desktop/progs/rsoi/env/lib/python3.7/site-packages/requests/models.py", line 387, in prepare_url
    raise MissingSchema(error)
requests.exceptions.MissingSchema: Invalid URL 'rsoi-online-store-auth.herokuapp.com/register/': No schema supplied. Perhaps you meant http://rsoi-online-store-auth.herokuapp.com/register/?
"POST /register/ HTTP/1.1" 500 17014
/Users/malenkijkotik/Desktop/progs/rsoi-online-store/online-store-customers/customers_app/requesters/authrequester.py changed, reloading.
Watching for file changes with StatReloader
Internal Server Error: /register/
"POST /register/ HTTP/1.1" 500 0
/Users/malenkijkotik/Desktop/progs/rsoi-online-store/online-store-customers/customers_app/requesters/authrequester.py changed, reloading.
Watching for file changes with StatReloader
/Users/malenkijkotik/Desktop/progs/rsoi-online-store/online-store-customers/customers_app/requesters/authrequester.py changed, reloading.
Watching for file changes with StatReloader
Internal Server Error: /register/
Traceback (most recent call last):
  File "/Users/malenkijkotik/Desktop/progs/rsoi/env/lib/python3.7/site-packages/urllib3/response.py", line 425, in _error_catcher
    yield
  File "/Users/malenkijkotik/Desktop/progs/rsoi/env/lib/python3.7/site-packages/urllib3/response.py", line 755, in read_chunked
    chunk = self._handle_chunk(amt)
  File "/Users/malenkijkotik/Desktop/progs/rsoi/env/lib/python3.7/site-packages/urllib3/response.py", line 699, in _handle_chunk
    value = self._fp._safe_read(amt)
  File "/Library/Frameworks/Python.framework/Versions/3.7/lib/python3.7/http/client.py", line 612, in _safe_read
    raise IncompleteRead(b''.join(s), amt)
http.client.IncompleteRead: IncompleteRead(2786 bytes read, 7454 more expected)

During handling of the above exception, another exception occurred:

Traceback (most recent call last):
  File "/Users/malenkijkotik/Desktop/progs/rsoi/env/lib/python3.7/site-packages/requests/models.py", line 750, in generate
    for chunk in self.raw.stream(chunk_size, decode_content=True):
  File "/Users/malenkijkotik/Desktop/progs/rsoi/env/lib/python3.7/site-packages/urllib3/response.py", line 560, in stream
    for line in self.read_chunked(amt, decode_content=decode_content):
  File "/Users/malenkijkotik/Desktop/progs/rsoi/env/lib/python3.7/site-packages/urllib3/response.py", line 781, in read_chunked
    self._original_response.close()
  File "/Library/Frameworks/Python.framework/Versions/3.7/lib/python3.7/contextlib.py", line 130, in __exit__
    self.gen.throw(type, value, traceback)
  File "/Users/malenkijkotik/Desktop/progs/rsoi/env/lib/python3.7/site-packages/urllib3/response.py", line 443, in _error_catcher
    raise ProtocolError("Connection broken: %r" % e, e)
urllib3.exceptions.ProtocolError: ('Connection broken: IncompleteRead(2786 bytes read, 7454 more expected)', IncompleteRead(2786 bytes read, 7454 more expected))

During handling of the above exception, another exception occurred:

Traceback (most recent call last):
  File "/Users/malenkijkotik/Desktop/progs/rsoi/env/lib/python3.7/site-packages/django/core/handlers/exception.py", line 34, in inner
    response = get_response(request)
  File "/Users/malenkijkotik/Desktop/progs/rsoi/env/lib/python3.7/site-packages/django/core/handlers/base.py", line 115, in _get_response
    response = self.process_exception_by_middleware(e, request)
  File "/Users/malenkijkotik/Desktop/progs/rsoi/env/lib/python3.7/site-packages/django/core/handlers/base.py", line 113, in _get_response
    response = wrapped_callback(request, *callback_args, **callback_kwargs)
  File "/Users/malenkijkotik/Desktop/progs/rsoi/env/lib/python3.7/site-packages/django/views/decorators/csrf.py", line 54, in wrapped_view
    return view_func(*args, **kwargs)
  File "/Users/malenkijkotik/Desktop/progs/rsoi/env/lib/python3.7/site-packages/django/views/generic/base.py", line 71, in view
    return self.dispatch(request, *args, **kwargs)
  File "/Users/malenkijkotik/Desktop/progs/rsoi/env/lib/python3.7/site-packages/rest_framework/views.py", line 497, in dispatch
    response = self.handle_exception(exc)
  File "/Users/malenkijkotik/Desktop/progs/rsoi/env/lib/python3.7/site-packages/rest_framework/views.py", line 457, in handle_exception
    self.raise_uncaught_exception(exc)
  File "/Users/malenkijkotik/Desktop/progs/rsoi/env/lib/python3.7/site-packages/rest_framework/views.py", line 468, in raise_uncaught_exception
    raise exc
  File "/Users/malenkijkotik/Desktop/progs/rsoi/env/lib/python3.7/site-packages/rest_framework/views.py", line 494, in dispatch
    response = handler(request, *args, **kwargs)
  File "/Users/malenkijkotik/Desktop/progs/rsoi-online-store/online-store-customers/customers_app/views.py", line 88, in post
    response, status_code = AuthRequester().register(request.data['username'], request.data['password'])
  File "/Users/malenkijkotik/Desktop/progs/rsoi-online-store/online-store-customers/customers_app/requesters/authrequester.py", line 22, in register
    response = self.post_request(self.AUTH_HOST + 'register/', data=data)
  File "/Users/malenkijkotik/Desktop/progs/rsoi-online-store/online-store-customers/customers_app/requesters/requester.py", line 19, in post_request
    response = requests.post(url=url, json=data, headers=headers)
  File "/Users/malenkijkotik/Desktop/progs/rsoi/env/lib/python3.7/site-packages/requests/api.py", line 116, in post
    return request('post', url, data=data, json=json, **kwargs)
  File "/Users/malenkijkotik/Desktop/progs/rsoi/env/lib/python3.7/site-packages/requests/api.py", line 60, in request
    return session.request(method=method, url=url, **kwargs)
  File "/Users/malenkijkotik/Desktop/progs/rsoi/env/lib/python3.7/site-packages/requests/sessions.py", line 533, in request
    resp = self.send(prep, **send_kwargs)
  File "/Users/malenkijkotik/Desktop/progs/rsoi/env/lib/python3.7/site-packages/requests/sessions.py", line 686, in send
    r.content
  File "/Users/malenkijkotik/Desktop/progs/rsoi/env/lib/python3.7/site-packages/requests/models.py", line 828, in content
    self._content = b''.join(self.iter_content(CONTENT_CHUNK_SIZE)) or b''
  File "/Users/malenkijkotik/Desktop/progs/rsoi/env/lib/python3.7/site-packages/requests/models.py", line 753, in generate
    raise ChunkedEncodingError(e)
requests.exceptions.ChunkedEncodingError: ('Connection broken: IncompleteRead(2786 bytes read, 7454 more expected)', IncompleteRead(2786 bytes read, 7454 more expected))
"POST /register/ HTTP/1.1" 500 18882
Internal Server Error: /register/
"POST /register/ HTTP/1.1" 500 0
Watching for file changes with StatReloader
Internal Server Error: /register/
"POST /register/ HTTP/1.1" 500 0
/Users/malenkijkotik/Desktop/progs/rsoi-online-store/online-store-customers/customers_app/requesters/authrequester.py changed, reloading.
Watching for file changes with StatReloader
Internal Server Error: /register/
"POST /register/ HTTP/1.1" 500 0
/Users/malenkijkotik/Desktop/progs/rsoi-online-store/online-store-customers/customers_app/views.py changed, reloading.
Watching for file changes with StatReloader
/Users/malenkijkotik/Desktop/progs/rsoi-online-store/online-store-customers/customers_app/views.py changed, reloading.
Watching for file changes with StatReloader
"POST /register/ HTTP/1.1" 201 656
Watching for file changes with StatReloader
Watching for file changes with StatReloader
Watching for file changes with StatReloader
Bad Request: /register/
"POST /register/ HTTP/1.1" 400 114
/Users/malenkijkotik/Desktop/progs/rsoi-online-store/online-store-customers/customers_app/requesters/authrequester.py changed, reloading.
Watching for file changes with StatReloader
Bad Request: /register/
"POST /register/ HTTP/1.1" 400 114
Internal Server Error: /register/
Traceback (most recent call last):
  File "/Users/malenkijkotik/Desktop/progs/rsoi/env/lib/python3.7/site-packages/django/core/handlers/exception.py", line 34, in inner
    response = get_response(request)
  File "/Users/malenkijkotik/Desktop/progs/rsoi/env/lib/python3.7/site-packages/django/core/handlers/base.py", line 115, in _get_response
    response = self.process_exception_by_middleware(e, request)
  File "/Users/malenkijkotik/Desktop/progs/rsoi/env/lib/python3.7/site-packages/django/core/handlers/base.py", line 113, in _get_response
    response = wrapped_callback(request, *callback_args, **callback_kwargs)
  File "/Users/malenkijkotik/Desktop/progs/rsoi/env/lib/python3.7/site-packages/django/views/decorators/csrf.py", line 54, in wrapped_view
    return view_func(*args, **kwargs)
  File "/Users/malenkijkotik/Desktop/progs/rsoi/env/lib/python3.7/site-packages/django/views/generic/base.py", line 71, in view
    return self.dispatch(request, *args, **kwargs)
  File "/Users/malenkijkotik/Desktop/progs/rsoi/env/lib/python3.7/site-packages/rest_framework/views.py", line 497, in dispatch
    response = self.handle_exception(exc)
  File "/Users/malenkijkotik/Desktop/progs/rsoi/env/lib/python3.7/site-packages/rest_framework/views.py", line 457, in handle_exception
    self.raise_uncaught_exception(exc)
  File "/Users/malenkijkotik/Desktop/progs/rsoi/env/lib/python3.7/site-packages/rest_framework/views.py", line 468, in raise_uncaught_exception
    raise exc
  File "/Users/malenkijkotik/Desktop/progs/rsoi/env/lib/python3.7/site-packages/rest_framework/views.py", line 494, in dispatch
    response = handler(request, *args, **kwargs)
  File "/Users/malenkijkotik/Desktop/progs/rsoi-online-store/online-store-customers/customers_app/views.py", line 104, in post
    order_uuid = order_response['uuid']
TypeError: 'Response' object is not subscriptable
"POST /register/ HTTP/1.1" 500 15504
/Users/malenkijkotik/Desktop/progs/rsoi-online-store/online-store-customers/customers_app/views.py changed, reloading.
Watching for file changes with StatReloader
"POST /register/ HTTP/1.1" 201 665
Watching for file changes with StatReloader
"POST /register/ HTTP/1.1" 201 665
/Users/malenkijkotik/Desktop/progs/rsoi-online-store/online-store-customers/customers_app/requesters/orders_requesters.py changed, reloading.
Watching for file changes with StatReloader
/Users/malenkijkotik/Desktop/progs/rsoi-online-store/online-store-customers/customers_app/requesters/authrequester.py changed, reloading.
Watching for file changes with StatReloader
Watching for file changes with StatReloader
Not Found: /
"GET / HTTP/1.1" 404 2434
"GET /all_customers HTTP/1.1" 301 0
Internal Server Error: /all_customers/
Traceback (most recent call last):
  File "/Users/malenkijkotik/Desktop/progs/rsoi/env/lib/python3.7/site-packages/django/core/handlers/exception.py", line 34, in inner
    response = get_response(request)
  File "/Users/malenkijkotik/Desktop/progs/rsoi/env/lib/python3.7/site-packages/django/core/handlers/base.py", line 115, in _get_response
    response = self.process_exception_by_middleware(e, request)
  File "/Users/malenkijkotik/Desktop/progs/rsoi/env/lib/python3.7/site-packages/django/core/handlers/base.py", line 113, in _get_response
    response = wrapped_callback(request, *callback_args, **callback_kwargs)
  File "/Users/malenkijkotik/Desktop/progs/rsoi/env/lib/python3.7/site-packages/django/views/decorators/csrf.py", line 54, in wrapped_view
    return view_func(*args, **kwargs)
  File "/Users/malenkijkotik/Desktop/progs/rsoi/env/lib/python3.7/site-packages/django/views/generic/base.py", line 71, in view
    return self.dispatch(request, *args, **kwargs)
  File "/Users/malenkijkotik/Desktop/progs/rsoi/env/lib/python3.7/site-packages/rest_framework/views.py", line 497, in dispatch
    response = self.handle_exception(exc)
  File "/Users/malenkijkotik/Desktop/progs/rsoi/env/lib/python3.7/site-packages/rest_framework/views.py", line 457, in handle_exception
    self.raise_uncaught_exception(exc)
  File "/Users/malenkijkotik/Desktop/progs/rsoi/env/lib/python3.7/site-packages/rest_framework/views.py", line 468, in raise_uncaught_exception
    raise exc
  File "/Users/malenkijkotik/Desktop/progs/rsoi/env/lib/python3.7/site-packages/rest_framework/views.py", line 494, in dispatch
    response = handler(request, *args, **kwargs)
  File "/Users/malenkijkotik/Desktop/progs/rsoi-online-store/online-store-customers/customers_app/views.py", line 33, in get
    customer['orders'][i] = order_response[0].json()
  File "/Users/malenkijkotik/Desktop/progs/rsoi/env/lib/python3.7/site-packages/requests/models.py", line 897, in json
    return complexjson.loads(self.text, **kwargs)
  File "/Library/Frameworks/Python.framework/Versions/3.7/lib/python3.7/json/__init__.py", line 348, in loads
    return _default_decoder.decode(s)
  File "/Library/Frameworks/Python.framework/Versions/3.7/lib/python3.7/json/decoder.py", line 337, in decode
    obj, end = self.raw_decode(s, idx=_w(s, 0).end())
  File "/Library/Frameworks/Python.framework/Versions/3.7/lib/python3.7/json/decoder.py", line 355, in raw_decode
    raise JSONDecodeError("Expecting value", s, err.value) from None
json.decoder.JSONDecodeError: Expecting value: line 1 column 1 (char 0)
"GET /all_customers/ HTTP/1.1" 500 16499
Internal Server Error: /all_customers/
Traceback (most recent call last):
  File "/Users/malenkijkotik/Desktop/progs/rsoi/env/lib/python3.7/site-packages/django/core/handlers/exception.py", line 34, in inner
    response = get_response(request)
  File "/Users/malenkijkotik/Desktop/progs/rsoi/env/lib/python3.7/site-packages/django/core/handlers/base.py", line 115, in _get_response
    response = self.process_exception_by_middleware(e, request)
  File "/Users/malenkijkotik/Desktop/progs/rsoi/env/lib/python3.7/site-packages/django/core/handlers/base.py", line 113, in _get_response
    response = wrapped_callback(request, *callback_args, **callback_kwargs)
  File "/Users/malenkijkotik/Desktop/progs/rsoi/env/lib/python3.7/site-packages/django/views/decorators/csrf.py", line 54, in wrapped_view
    return view_func(*args, **kwargs)
  File "/Users/malenkijkotik/Desktop/progs/rsoi/env/lib/python3.7/site-packages/django/views/generic/base.py", line 71, in view
    return self.dispatch(request, *args, **kwargs)
  File "/Users/malenkijkotik/Desktop/progs/rsoi/env/lib/python3.7/site-packages/rest_framework/views.py", line 497, in dispatch
    response = self.handle_exception(exc)
  File "/Users/malenkijkotik/Desktop/progs/rsoi/env/lib/python3.7/site-packages/rest_framework/views.py", line 457, in handle_exception
    self.raise_uncaught_exception(exc)
  File "/Users/malenkijkotik/Desktop/progs/rsoi/env/lib/python3.7/site-packages/rest_framework/views.py", line 468, in raise_uncaught_exception
    raise exc
  File "/Users/malenkijkotik/Desktop/progs/rsoi/env/lib/python3.7/site-packages/rest_framework/views.py", line 494, in dispatch
    response = handler(request, *args, **kwargs)
  File "/Users/malenkijkotik/Desktop/progs/rsoi-online-store/online-store-customers/customers_app/views.py", line 33, in get
    customer['orders'][i] = order_response[0].json()
  File "/Users/malenkijkotik/Desktop/progs/rsoi/env/lib/python3.7/site-packages/requests/models.py", line 897, in json
    return complexjson.loads(self.text, **kwargs)
  File "/Library/Frameworks/Python.framework/Versions/3.7/lib/python3.7/json/__init__.py", line 348, in loads
    return _default_decoder.decode(s)
  File "/Library/Frameworks/Python.framework/Versions/3.7/lib/python3.7/json/decoder.py", line 337, in decode
    obj, end = self.raw_decode(s, idx=_w(s, 0).end())
  File "/Library/Frameworks/Python.framework/Versions/3.7/lib/python3.7/json/decoder.py", line 355, in raw_decode
    raise JSONDecodeError("Expecting value", s, err.value) from None
json.decoder.JSONDecodeError: Expecting value: line 1 column 1 (char 0)
"GET /all_customers/ HTTP/1.1" 500 16454
Internal Server Error: /all_customers/
Traceback (most recent call last):
  File "/Users/malenkijkotik/Desktop/progs/rsoi/env/lib/python3.7/site-packages/django/core/handlers/exception.py", line 34, in inner
    response = get_response(request)
  File "/Users/malenkijkotik/Desktop/progs/rsoi/env/lib/python3.7/site-packages/django/core/handlers/base.py", line 115, in _get_response
    response = self.process_exception_by_middleware(e, request)
  File "/Users/malenkijkotik/Desktop/progs/rsoi/env/lib/python3.7/site-packages/django/core/handlers/base.py", line 113, in _get_response
    response = wrapped_callback(request, *callback_args, **callback_kwargs)
  File "/Users/malenkijkotik/Desktop/progs/rsoi/env/lib/python3.7/site-packages/django/views/decorators/csrf.py", line 54, in wrapped_view
    return view_func(*args, **kwargs)
  File "/Users/malenkijkotik/Desktop/progs/rsoi/env/lib/python3.7/site-packages/django/views/generic/base.py", line 71, in view
    return self.dispatch(request, *args, **kwargs)
  File "/Users/malenkijkotik/Desktop/progs/rsoi/env/lib/python3.7/site-packages/rest_framework/views.py", line 497, in dispatch
    response = self.handle_exception(exc)
  File "/Users/malenkijkotik/Desktop/progs/rsoi/env/lib/python3.7/site-packages/rest_framework/views.py", line 457, in handle_exception
    self.raise_uncaught_exception(exc)
  File "/Users/malenkijkotik/Desktop/progs/rsoi/env/lib/python3.7/site-packages/rest_framework/views.py", line 468, in raise_uncaught_exception
    raise exc
  File "/Users/malenkijkotik/Desktop/progs/rsoi/env/lib/python3.7/site-packages/rest_framework/views.py", line 494, in dispatch
    response = handler(request, *args, **kwargs)
  File "/Users/malenkijkotik/Desktop/progs/rsoi-online-store/online-store-customers/customers_app/views.py", line 33, in get
    customer['orders'][i] = order_response[0].json()
  File "/Users/malenkijkotik/Desktop/progs/rsoi/env/lib/python3.7/site-packages/requests/models.py", line 897, in json
    return complexjson.loads(self.text, **kwargs)
  File "/Library/Frameworks/Python.framework/Versions/3.7/lib/python3.7/json/__init__.py", line 348, in loads
    return _default_decoder.decode(s)
  File "/Library/Frameworks/Python.framework/Versions/3.7/lib/python3.7/json/decoder.py", line 337, in decode
    obj, end = self.raw_decode(s, idx=_w(s, 0).end())
  File "/Library/Frameworks/Python.framework/Versions/3.7/lib/python3.7/json/decoder.py", line 355, in raw_decode
    raise JSONDecodeError("Expecting value", s, err.value) from None
json.decoder.JSONDecodeError: Expecting value: line 1 column 1 (char 0)
"GET /all_customers/ HTTP/1.1" 500 16454
Not Found: /all_customers/1/
"GET /all_customers/1/ HTTP/1.1" 404 0
/Users/malenkijkotik/Desktop/progs/rsoi-online-store/online-store-customers/customers_app/views.py changed, reloading.
Watching for file changes with StatReloader
Not Found: /all_customers/1/
"GET /all_customers/1/ HTTP/1.1" 404 0
Internal Server Error: /all_customers/
Traceback (most recent call last):
  File "/Users/malenkijkotik/Desktop/progs/rsoi/env/lib/python3.7/site-packages/django/core/handlers/exception.py", line 34, in inner
    response = get_response(request)
  File "/Users/malenkijkotik/Desktop/progs/rsoi/env/lib/python3.7/site-packages/django/core/handlers/base.py", line 115, in _get_response
    response = self.process_exception_by_middleware(e, request)
  File "/Users/malenkijkotik/Desktop/progs/rsoi/env/lib/python3.7/site-packages/django/core/handlers/base.py", line 113, in _get_response
    response = wrapped_callback(request, *callback_args, **callback_kwargs)
  File "/Users/malenkijkotik/Desktop/progs/rsoi/env/lib/python3.7/site-packages/django/views/decorators/csrf.py", line 54, in wrapped_view
    return view_func(*args, **kwargs)
  File "/Users/malenkijkotik/Desktop/progs/rsoi/env/lib/python3.7/site-packages/django/views/generic/base.py", line 71, in view
    return self.dispatch(request, *args, **kwargs)
  File "/Users/malenkijkotik/Desktop/progs/rsoi/env/lib/python3.7/site-packages/rest_framework/views.py", line 497, in dispatch
    response = self.handle_exception(exc)
  File "/Users/malenkijkotik/Desktop/progs/rsoi/env/lib/python3.7/site-packages/rest_framework/views.py", line 457, in handle_exception
    self.raise_uncaught_exception(exc)
  File "/Users/malenkijkotik/Desktop/progs/rsoi/env/lib/python3.7/site-packages/rest_framework/views.py", line 468, in raise_uncaught_exception
    raise exc
  File "/Users/malenkijkotik/Desktop/progs/rsoi/env/lib/python3.7/site-packages/rest_framework/views.py", line 494, in dispatch
    response = handler(request, *args, **kwargs)
  File "/Users/malenkijkotik/Desktop/progs/rsoi-online-store/online-store-customers/customers_app/views.py", line 34, in get
    customer['orders'][i] = order_response[0].json()
  File "/Users/malenkijkotik/Desktop/progs/rsoi/env/lib/python3.7/site-packages/requests/models.py", line 897, in json
    return complexjson.loads(self.text, **kwargs)
  File "/Library/Frameworks/Python.framework/Versions/3.7/lib/python3.7/json/__init__.py", line 348, in loads
    return _default_decoder.decode(s)
  File "/Library/Frameworks/Python.framework/Versions/3.7/lib/python3.7/json/decoder.py", line 337, in decode
    obj, end = self.raw_decode(s, idx=_w(s, 0).end())
  File "/Library/Frameworks/Python.framework/Versions/3.7/lib/python3.7/json/decoder.py", line 355, in raw_decode
    raise JSONDecodeError("Expecting value", s, err.value) from None
json.decoder.JSONDecodeError: Expecting value: line 1 column 1 (char 0)
"GET /all_customers/ HTTP/1.1" 500 16454
/Users/malenkijkotik/Desktop/progs/rsoi-online-store/online-store-customers/customers_app/views.py changed, reloading.
Watching for file changes with StatReloader
Internal Server Error: /all_customers/
Traceback (most recent call last):
  File "/Users/malenkijkotik/Desktop/progs/rsoi/env/lib/python3.7/site-packages/django/core/handlers/exception.py", line 34, in inner
    response = get_response(request)
  File "/Users/malenkijkotik/Desktop/progs/rsoi/env/lib/python3.7/site-packages/django/core/handlers/base.py", line 115, in _get_response
    response = self.process_exception_by_middleware(e, request)
  File "/Users/malenkijkotik/Desktop/progs/rsoi/env/lib/python3.7/site-packages/django/core/handlers/base.py", line 113, in _get_response
    response = wrapped_callback(request, *callback_args, **callback_kwargs)
  File "/Users/malenkijkotik/Desktop/progs/rsoi/env/lib/python3.7/site-packages/django/views/decorators/csrf.py", line 54, in wrapped_view
    return view_func(*args, **kwargs)
  File "/Users/malenkijkotik/Desktop/progs/rsoi/env/lib/python3.7/site-packages/django/views/generic/base.py", line 71, in view
    return self.dispatch(request, *args, **kwargs)
  File "/Users/malenkijkotik/Desktop/progs/rsoi/env/lib/python3.7/site-packages/rest_framework/views.py", line 497, in dispatch
    response = self.handle_exception(exc)
  File "/Users/malenkijkotik/Desktop/progs/rsoi/env/lib/python3.7/site-packages/rest_framework/views.py", line 457, in handle_exception
    self.raise_uncaught_exception(exc)
  File "/Users/malenkijkotik/Desktop/progs/rsoi/env/lib/python3.7/site-packages/rest_framework/views.py", line 468, in raise_uncaught_exception
    raise exc
  File "/Users/malenkijkotik/Desktop/progs/rsoi/env/lib/python3.7/site-packages/rest_framework/views.py", line 494, in dispatch
    response = handler(request, *args, **kwargs)
  File "/Users/malenkijkotik/Desktop/progs/rsoi-online-store/online-store-customers/customers_app/views.py", line 37, in get
    customer['orders'][i] = order_response[0].json()
  File "/Users/malenkijkotik/Desktop/progs/rsoi/env/lib/python3.7/site-packages/requests/models.py", line 897, in json
    return complexjson.loads(self.text, **kwargs)
  File "/Library/Frameworks/Python.framework/Versions/3.7/lib/python3.7/json/__init__.py", line 348, in loads
    return _default_decoder.decode(s)
  File "/Library/Frameworks/Python.framework/Versions/3.7/lib/python3.7/json/decoder.py", line 337, in decode
    obj, end = self.raw_decode(s, idx=_w(s, 0).end())
  File "/Library/Frameworks/Python.framework/Versions/3.7/lib/python3.7/json/decoder.py", line 355, in raw_decode
    raise JSONDecodeError("Expecting value", s, err.value) from None
json.decoder.JSONDecodeError: Expecting value: line 1 column 1 (char 0)
"GET /all_customers/ HTTP/1.1" 500 16454
/Users/malenkijkotik/Desktop/progs/rsoi-online-store/online-store-customers/customers_app/views.py changed, reloading.
Watching for file changes with StatReloader
Internal Server Error: /all_customers/
Traceback (most recent call last):
  File "/Users/malenkijkotik/Desktop/progs/rsoi/env/lib/python3.7/site-packages/django/core/handlers/exception.py", line 34, in inner
    response = get_response(request)
  File "/Users/malenkijkotik/Desktop/progs/rsoi/env/lib/python3.7/site-packages/django/core/handlers/base.py", line 115, in _get_response
    response = self.process_exception_by_middleware(e, request)
  File "/Users/malenkijkotik/Desktop/progs/rsoi/env/lib/python3.7/site-packages/django/core/handlers/base.py", line 113, in _get_response
    response = wrapped_callback(request, *callback_args, **callback_kwargs)
  File "/Users/malenkijkotik/Desktop/progs/rsoi/env/lib/python3.7/site-packages/django/views/decorators/csrf.py", line 54, in wrapped_view
    return view_func(*args, **kwargs)
  File "/Users/malenkijkotik/Desktop/progs/rsoi/env/lib/python3.7/site-packages/django/views/generic/base.py", line 71, in view
    return self.dispatch(request, *args, **kwargs)
  File "/Users/malenkijkotik/Desktop/progs/rsoi/env/lib/python3.7/site-packages/rest_framework/views.py", line 497, in dispatch
    response = self.handle_exception(exc)
  File "/Users/malenkijkotik/Desktop/progs/rsoi/env/lib/python3.7/site-packages/rest_framework/views.py", line 457, in handle_exception
    self.raise_uncaught_exception(exc)
  File "/Users/malenkijkotik/Desktop/progs/rsoi/env/lib/python3.7/site-packages/rest_framework/views.py", line 468, in raise_uncaught_exception
    raise exc
  File "/Users/malenkijkotik/Desktop/progs/rsoi/env/lib/python3.7/site-packages/rest_framework/views.py", line 494, in dispatch
    response = handler(request, *args, **kwargs)
  File "/Users/malenkijkotik/Desktop/progs/rsoi-online-store/online-store-customers/customers_app/views.py", line 37, in get
    customer['orders'][i] = order_response[0].json()
  File "/Users/malenkijkotik/Desktop/progs/rsoi/env/lib/python3.7/site-packages/requests/models.py", line 897, in json
    return complexjson.loads(self.text, **kwargs)
  File "/Library/Frameworks/Python.framework/Versions/3.7/lib/python3.7/json/__init__.py", line 348, in loads
    return _default_decoder.decode(s)
  File "/Library/Frameworks/Python.framework/Versions/3.7/lib/python3.7/json/decoder.py", line 337, in decode
    obj, end = self.raw_decode(s, idx=_w(s, 0).end())
  File "/Library/Frameworks/Python.framework/Versions/3.7/lib/python3.7/json/decoder.py", line 355, in raw_decode
    raise JSONDecodeError("Expecting value", s, err.value) from None
json.decoder.JSONDecodeError: Expecting value: line 1 column 1 (char 0)
"GET /all_customers/ HTTP/1.1" 500 16454
/Users/malenkijkotik/Desktop/progs/rsoi-online-store/online-store-customers/customers_app/views.py changed, reloading.
Watching for file changes with StatReloader
"GET /all_customers/ HTTP/1.1" 200 621
Not Found: /all_customers/31/
"DELETE /all_customers/31/ HTTP/1.1" 404 0
/Users/malenkijkotik/Desktop/progs/rsoi-online-store/online-store-customers/customers_app/views.py changed, reloading.
Watching for file changes with StatReloader
/Users/malenkijkotik/Desktop/progs/rsoi-online-store/online-store-customers/customers_app/views.py changed, reloading.
Watching for file changes with StatReloader
/Users/malenkijkotik/Desktop/progs/rsoi-online-store/online-store-customers/customers_app/views.py changed, reloading.
Watching for file changes with StatReloader
/Users/malenkijkotik/Desktop/progs/rsoi-online-store/online-store-customers/customers_app/views.py changed, reloading.
Watching for file changes with StatReloader
/Users/malenkijkotik/Desktop/progs/rsoi-online-store/online-store-customers/customers_app/views.py changed, reloading.
Watching for file changes with StatReloader
/Users/malenkijkotik/Desktop/progs/rsoi-online-store/online-store-customers/customers_app/views.py changed, reloading.
Watching for file changes with StatReloader
/Users/malenkijkotik/Desktop/progs/rsoi-online-store/online-store-customers/customers_app/views.py changed, reloading.
Watching for file changes with StatReloader
/Users/malenkijkotik/Desktop/progs/rsoi-online-store/online-store-customers/customers_app/urls.py changed, reloading.
Watching for file changes with StatReloader
/Users/malenkijkotik/Desktop/progs/rsoi-online-store/online-store-customers/customers_app/urls.py changed, reloading.
Watching for file changes with StatReloader
/Users/malenkijkotik/Desktop/progs/rsoi-online-store/online-store-customers/customers_app/requesters/orders_requesters.py changed, reloading.
Watching for file changes with StatReloader
Internal Server Error: /all_customers/
Traceback (most recent call last):
  File "/Users/malenkijkotik/Desktop/progs/rsoi/env/lib/python3.7/site-packages/django/core/handlers/exception.py", line 34, in inner
    response = get_response(request)
  File "/Users/malenkijkotik/Desktop/progs/rsoi/env/lib/python3.7/site-packages/django/core/handlers/base.py", line 115, in _get_response
    response = self.process_exception_by_middleware(e, request)
  File "/Users/malenkijkotik/Desktop/progs/rsoi/env/lib/python3.7/site-packages/django/core/handlers/base.py", line 113, in _get_response
    response = wrapped_callback(request, *callback_args, **callback_kwargs)
  File "/Users/malenkijkotik/Desktop/progs/rsoi/env/lib/python3.7/site-packages/django/views/decorators/csrf.py", line 54, in wrapped_view
    return view_func(*args, **kwargs)
  File "/Users/malenkijkotik/Desktop/progs/rsoi/env/lib/python3.7/site-packages/django/views/generic/base.py", line 71, in view
    return self.dispatch(request, *args, **kwargs)
  File "/Users/malenkijkotik/Desktop/progs/rsoi/env/lib/python3.7/site-packages/rest_framework/views.py", line 497, in dispatch
    response = self.handle_exception(exc)
  File "/Users/malenkijkotik/Desktop/progs/rsoi/env/lib/python3.7/site-packages/rest_framework/views.py", line 457, in handle_exception
    self.raise_uncaught_exception(exc)
  File "/Users/malenkijkotik/Desktop/progs/rsoi/env/lib/python3.7/site-packages/rest_framework/views.py", line 468, in raise_uncaught_exception
    raise exc
  File "/Users/malenkijkotik/Desktop/progs/rsoi/env/lib/python3.7/site-packages/rest_framework/views.py", line 494, in dispatch
    response = handler(request, *args, **kwargs)
  File "/Users/malenkijkotik/Desktop/progs/rsoi-online-store/online-store-customers/customers_app/views.py", line 35, in get
    customer['orders'][i] = order_response[0].json()
TypeError: 'Response' object does not support indexing
"GET /all_customers/ HTTP/1.1" 500 15607
/Users/malenkijkotik/Desktop/progs/rsoi-online-store/online-store-customers/customers_app/views.py changed, reloading.
Watching for file changes with StatReloader
/Users/malenkijkotik/Desktop/progs/rsoi-online-store/online-store-customers/customers_app/views.py changed, reloading.
Watching for file changes with StatReloader
"GET /all_customers/ HTTP/1.1" 200 811
Not Found: /create_new_order/31/
"GET /create_new_order/31/ HTTP/1.1" 404 2703
Not Found: /create_new_order/31/
"GET /create_new_order/31/ HTTP/1.1" 404 2703
/Users/malenkijkotik/Desktop/progs/rsoi-online-store/online-store-customers/customers_app/views.py changed, reloading.
Watching for file changes with StatReloader
Not Found: /create_new_order/31/
"GET /create_new_order/31/ HTTP/1.1" 404 2703
/Users/malenkijkotik/Desktop/progs/rsoi-online-store/online-store-customers/customers_app/views.py changed, reloading.
Watching for file changes with StatReloader
Not Found: /create_new_order/31/
"GET /create_new_order/31/ HTTP/1.1" 404 2703
/Users/malenkijkotik/Desktop/progs/rsoi-online-store/online-store-customers/customers_app/urls.py changed, reloading.
Watching for file changes with StatReloader
Internal Server Error: /create_new_order/31/
"GET /create_new_order/31/ HTTP/1.1" 500 0
Bad Request: /create_new_order/31/
"GET /create_new_order/31/ HTTP/1.1" 400 75
/Users/malenkijkotik/Desktop/progs/rsoi-online-store/online-store-customers/customers_app/views.py changed, reloading.
Watching for file changes with StatReloader
/Users/malenkijkotik/Desktop/progs/rsoi-online-store/online-store-customers/customers_app/views.py changed, reloading.
Watching for file changes with StatReloader
/Users/malenkijkotik/Desktop/progs/rsoi-online-store/online-store-customers/customers_app/views.py changed, reloading.
Watching for file changes with StatReloader
Bad Request: /create_new_order/31/
"GET /create_new_order/31/ HTTP/1.1" 400 1192
/Users/malenkijkotik/Desktop/progs/rsoi-online-store/online-store-customers/customers_app/serializers.py changed, reloading.
Watching for file changes with StatReloader
/Users/malenkijkotik/Desktop/progs/rsoi-online-store/online-store-customers/customers_app/views.py changed, reloading.
Watching for file changes with StatReloader
Internal Server Error: /create_new_order/31/
Traceback (most recent call last):
  File "/Users/malenkijkotik/Desktop/progs/rsoi/env/lib/python3.7/site-packages/django/core/handlers/exception.py", line 34, in inner
    response = get_response(request)
  File "/Users/malenkijkotik/Desktop/progs/rsoi/env/lib/python3.7/site-packages/django/core/handlers/base.py", line 115, in _get_response
    response = self.process_exception_by_middleware(e, request)
  File "/Users/malenkijkotik/Desktop/progs/rsoi/env/lib/python3.7/site-packages/django/core/handlers/base.py", line 113, in _get_response
    response = wrapped_callback(request, *callback_args, **callback_kwargs)
  File "/Users/malenkijkotik/Desktop/progs/rsoi/env/lib/python3.7/site-packages/django/views/decorators/csrf.py", line 54, in wrapped_view
    return view_func(*args, **kwargs)
  File "/Users/malenkijkotik/Desktop/progs/rsoi/env/lib/python3.7/site-packages/django/views/generic/base.py", line 71, in view
    return self.dispatch(request, *args, **kwargs)
  File "/Users/malenkijkotik/Desktop/progs/rsoi/env/lib/python3.7/site-packages/rest_framework/views.py", line 497, in dispatch
    response = self.handle_exception(exc)
  File "/Users/malenkijkotik/Desktop/progs/rsoi/env/lib/python3.7/site-packages/rest_framework/views.py", line 457, in handle_exception
    self.raise_uncaught_exception(exc)
  File "/Users/malenkijkotik/Desktop/progs/rsoi/env/lib/python3.7/site-packages/rest_framework/views.py", line 468, in raise_uncaught_exception
    raise exc
  File "/Users/malenkijkotik/Desktop/progs/rsoi/env/lib/python3.7/site-packages/rest_framework/views.py", line 494, in dispatch
    response = handler(request, *args, **kwargs)
  File "/Users/malenkijkotik/Desktop/progs/rsoi-online-store/online-store-customers/customers_app/views.py", line 136, in get
    serializer = CustomerSerializer.update(instance=customer, validated_data=new_orders)
TypeError: update() missing 1 required positional argument: 'self'
"GET /create_new_order/31/ HTTP/1.1" 500 15680
/Users/malenkijkotik/Desktop/progs/rsoi-online-store/online-store-customers/customers_app/views.py changed, reloading.
Watching for file changes with StatReloader
Internal Server Error: /create_new_order/31/
Traceback (most recent call last):
  File "/Users/malenkijkotik/Desktop/progs/rsoi/env/lib/python3.7/site-packages/django/db/models/fields/__init__.py", line 2343, in to_python
    return uuid.UUID(**{input_form: value})
  File "/Library/Frameworks/Python.framework/Versions/3.7/lib/python3.7/uuid.py", line 160, in __init__
    raise ValueError('badly formed hexadecimal UUID string')
ValueError: badly formed hexadecimal UUID string

During handling of the above exception, another exception occurred:

Traceback (most recent call last):
  File "/Users/malenkijkotik/Desktop/progs/rsoi/env/lib/python3.7/site-packages/django/core/handlers/exception.py", line 34, in inner
    response = get_response(request)
  File "/Users/malenkijkotik/Desktop/progs/rsoi/env/lib/python3.7/site-packages/django/core/handlers/base.py", line 115, in _get_response
    response = self.process_exception_by_middleware(e, request)
  File "/Users/malenkijkotik/Desktop/progs/rsoi/env/lib/python3.7/site-packages/django/core/handlers/base.py", line 113, in _get_response
    response = wrapped_callback(request, *callback_args, **callback_kwargs)
  File "/Users/malenkijkotik/Desktop/progs/rsoi/env/lib/python3.7/site-packages/django/views/decorators/csrf.py", line 54, in wrapped_view
    return view_func(*args, **kwargs)
  File "/Users/malenkijkotik/Desktop/progs/rsoi/env/lib/python3.7/site-packages/django/views/generic/base.py", line 71, in view
    return self.dispatch(request, *args, **kwargs)
  File "/Users/malenkijkotik/Desktop/progs/rsoi/env/lib/python3.7/site-packages/rest_framework/views.py", line 497, in dispatch
    response = self.handle_exception(exc)
  File "/Users/malenkijkotik/Desktop/progs/rsoi/env/lib/python3.7/site-packages/rest_framework/views.py", line 457, in handle_exception
    self.raise_uncaught_exception(exc)
  File "/Users/malenkijkotik/Desktop/progs/rsoi/env/lib/python3.7/site-packages/rest_framework/views.py", line 468, in raise_uncaught_exception
    raise exc
  File "/Users/malenkijkotik/Desktop/progs/rsoi/env/lib/python3.7/site-packages/rest_framework/views.py", line 494, in dispatch
    response = handler(request, *args, **kwargs)
  File "/Users/malenkijkotik/Desktop/progs/rsoi-online-store/online-store-customers/customers_app/views.py", line 136, in get
    serializer = CustomerSerializer().update(instance=customer, validated_data=new_orders)
  File "/Users/malenkijkotik/Desktop/progs/rsoi-online-store/online-store-customers/customers_app/serializers.py", line 18, in update
    instance.save()
  File "/Users/malenkijkotik/Desktop/progs/rsoi/env/lib/python3.7/site-packages/django/db/models/base.py", line 741, in save
    force_update=force_update, update_fields=update_fields)
  File "/Users/malenkijkotik/Desktop/progs/rsoi/env/lib/python3.7/site-packages/django/db/models/base.py", line 779, in save_base
    force_update, using, update_fields,
  File "/Users/malenkijkotik/Desktop/progs/rsoi/env/lib/python3.7/site-packages/django/db/models/base.py", line 851, in _save_table
    forced_update)
  File "/Users/malenkijkotik/Desktop/progs/rsoi/env/lib/python3.7/site-packages/django/db/models/base.py", line 900, in _do_update
    return filtered._update(values) > 0
  File "/Users/malenkijkotik/Desktop/progs/rsoi/env/lib/python3.7/site-packages/django/db/models/query.py", line 760, in _update
    return query.get_compiler(self.db).execute_sql(CURSOR)
  File "/Users/malenkijkotik/Desktop/progs/rsoi/env/lib/python3.7/site-packages/django/db/models/sql/compiler.py", line 1469, in execute_sql
    cursor = super().execute_sql(result_type)
  File "/Users/malenkijkotik/Desktop/progs/rsoi/env/lib/python3.7/site-packages/django/db/models/sql/compiler.py", line 1127, in execute_sql
    sql, params = self.as_sql()
  File "/Users/malenkijkotik/Desktop/progs/rsoi/env/lib/python3.7/site-packages/django/db/models/sql/compiler.py", line 1435, in as_sql
    val = field.get_db_prep_save(val, connection=self.connection)
  File "/Users/malenkijkotik/Desktop/progs/rsoi/env/lib/python3.7/site-packages/django/db/models/fields/__init__.py", line 793, in get_db_prep_save
    return self.get_db_prep_value(value, connection=connection, prepared=False)
  File "/Users/malenkijkotik/Desktop/progs/rsoi/env/lib/python3.7/site-packages/django/contrib/postgres/fields/array.py", line 91, in get_db_prep_value
    return [self.base_field.get_db_prep_value(i, connection, prepared=False) for i in value]
  File "/Users/malenkijkotik/Desktop/progs/rsoi/env/lib/python3.7/site-packages/django/contrib/postgres/fields/array.py", line 91, in <listcomp>
    return [self.base_field.get_db_prep_value(i, connection, prepared=False) for i in value]
  File "/Users/malenkijkotik/Desktop/progs/rsoi/env/lib/python3.7/site-packages/django/db/models/fields/__init__.py", line 2333, in get_db_prep_value
    value = self.to_python(value)
  File "/Users/malenkijkotik/Desktop/progs/rsoi/env/lib/python3.7/site-packages/django/db/models/fields/__init__.py", line 2348, in to_python
    params={'value': value},
django.core.exceptions.ValidationError: ["'d' is not a valid UUID."]
"GET /create_new_order/31/ HTTP/1.1" 500 18835
/Users/malenkijkotik/Desktop/progs/rsoi-online-store/online-store-customers/customers_app/views.py changed, reloading.
Watching for file changes with StatReloader
Internal Server Error: /create_new_order/31/
Traceback (most recent call last):
  File "/Users/malenkijkotik/Desktop/progs/rsoi/env/lib/python3.7/site-packages/django/db/models/fields/__init__.py", line 2343, in to_python
    return uuid.UUID(**{input_form: value})
  File "/Library/Frameworks/Python.framework/Versions/3.7/lib/python3.7/uuid.py", line 160, in __init__
    raise ValueError('badly formed hexadecimal UUID string')
ValueError: badly formed hexadecimal UUID string

During handling of the above exception, another exception occurred:

Traceback (most recent call last):
  File "/Users/malenkijkotik/Desktop/progs/rsoi/env/lib/python3.7/site-packages/django/core/handlers/exception.py", line 34, in inner
    response = get_response(request)
  File "/Users/malenkijkotik/Desktop/progs/rsoi/env/lib/python3.7/site-packages/django/core/handlers/base.py", line 115, in _get_response
    response = self.process_exception_by_middleware(e, request)
  File "/Users/malenkijkotik/Desktop/progs/rsoi/env/lib/python3.7/site-packages/django/core/handlers/base.py", line 113, in _get_response
    response = wrapped_callback(request, *callback_args, **callback_kwargs)
  File "/Users/malenkijkotik/Desktop/progs/rsoi/env/lib/python3.7/site-packages/django/views/decorators/csrf.py", line 54, in wrapped_view
    return view_func(*args, **kwargs)
  File "/Users/malenkijkotik/Desktop/progs/rsoi/env/lib/python3.7/site-packages/django/views/generic/base.py", line 71, in view
    return self.dispatch(request, *args, **kwargs)
  File "/Users/malenkijkotik/Desktop/progs/rsoi/env/lib/python3.7/site-packages/rest_framework/views.py", line 497, in dispatch
    response = self.handle_exception(exc)
  File "/Users/malenkijkotik/Desktop/progs/rsoi/env/lib/python3.7/site-packages/rest_framework/views.py", line 457, in handle_exception
    self.raise_uncaught_exception(exc)
  File "/Users/malenkijkotik/Desktop/progs/rsoi/env/lib/python3.7/site-packages/rest_framework/views.py", line 468, in raise_uncaught_exception
    raise exc
  File "/Users/malenkijkotik/Desktop/progs/rsoi/env/lib/python3.7/site-packages/rest_framework/views.py", line 494, in dispatch
    response = handler(request, *args, **kwargs)
  File "/Users/malenkijkotik/Desktop/progs/rsoi-online-store/online-store-customers/customers_app/views.py", line 137, in get
    serializer = CustomerSerializer().update(instance=customer, validated_data=new_orders)
  File "/Users/malenkijkotik/Desktop/progs/rsoi-online-store/online-store-customers/customers_app/serializers.py", line 18, in update
    instance.save()
  File "/Users/malenkijkotik/Desktop/progs/rsoi/env/lib/python3.7/site-packages/django/db/models/base.py", line 741, in save
    force_update=force_update, update_fields=update_fields)
  File "/Users/malenkijkotik/Desktop/progs/rsoi/env/lib/python3.7/site-packages/django/db/models/base.py", line 779, in save_base
    force_update, using, update_fields,
  File "/Users/malenkijkotik/Desktop/progs/rsoi/env/lib/python3.7/site-packages/django/db/models/base.py", line 851, in _save_table
    forced_update)
  File "/Users/malenkijkotik/Desktop/progs/rsoi/env/lib/python3.7/site-packages/django/db/models/base.py", line 900, in _do_update
    return filtered._update(values) > 0
  File "/Users/malenkijkotik/Desktop/progs/rsoi/env/lib/python3.7/site-packages/django/db/models/query.py", line 760, in _update
    return query.get_compiler(self.db).execute_sql(CURSOR)
  File "/Users/malenkijkotik/Desktop/progs/rsoi/env/lib/python3.7/site-packages/django/db/models/sql/compiler.py", line 1469, in execute_sql
    cursor = super().execute_sql(result_type)
  File "/Users/malenkijkotik/Desktop/progs/rsoi/env/lib/python3.7/site-packages/django/db/models/sql/compiler.py", line 1127, in execute_sql
    sql, params = self.as_sql()
  File "/Users/malenkijkotik/Desktop/progs/rsoi/env/lib/python3.7/site-packages/django/db/models/sql/compiler.py", line 1435, in as_sql
    val = field.get_db_prep_save(val, connection=self.connection)
  File "/Users/malenkijkotik/Desktop/progs/rsoi/env/lib/python3.7/site-packages/django/db/models/fields/__init__.py", line 793, in get_db_prep_save
    return self.get_db_prep_value(value, connection=connection, prepared=False)
  File "/Users/malenkijkotik/Desktop/progs/rsoi/env/lib/python3.7/site-packages/django/contrib/postgres/fields/array.py", line 91, in get_db_prep_value
    return [self.base_field.get_db_prep_value(i, connection, prepared=False) for i in value]
  File "/Users/malenkijkotik/Desktop/progs/rsoi/env/lib/python3.7/site-packages/django/contrib/postgres/fields/array.py", line 91, in <listcomp>
    return [self.base_field.get_db_prep_value(i, connection, prepared=False) for i in value]
  File "/Users/malenkijkotik/Desktop/progs/rsoi/env/lib/python3.7/site-packages/django/db/models/fields/__init__.py", line 2333, in get_db_prep_value
    value = self.to_python(value)
  File "/Users/malenkijkotik/Desktop/progs/rsoi/env/lib/python3.7/site-packages/django/db/models/fields/__init__.py", line 2348, in to_python
    params={'value': value},
django.core.exceptions.ValidationError: ["'d' is not a valid UUID."]
"GET /create_new_order/31/ HTTP/1.1" 500 18835
/Users/malenkijkotik/Desktop/progs/rsoi-online-store/online-store-customers/customers_app/views.py changed, reloading.
Watching for file changes with StatReloader
Internal Server Error: /create_new_order/31/
Traceback (most recent call last):
  File "/Users/malenkijkotik/Desktop/progs/rsoi/env/lib/python3.7/site-packages/django/core/handlers/exception.py", line 34, in inner
    response = get_response(request)
  File "/Users/malenkijkotik/Desktop/progs/rsoi/env/lib/python3.7/site-packages/django/core/handlers/base.py", line 115, in _get_response
    response = self.process_exception_by_middleware(e, request)
  File "/Users/malenkijkotik/Desktop/progs/rsoi/env/lib/python3.7/site-packages/django/core/handlers/base.py", line 113, in _get_response
    response = wrapped_callback(request, *callback_args, **callback_kwargs)
  File "/Users/malenkijkotik/Desktop/progs/rsoi/env/lib/python3.7/site-packages/django/views/decorators/csrf.py", line 54, in wrapped_view
    return view_func(*args, **kwargs)
  File "/Users/malenkijkotik/Desktop/progs/rsoi/env/lib/python3.7/site-packages/django/views/generic/base.py", line 71, in view
    return self.dispatch(request, *args, **kwargs)
  File "/Users/malenkijkotik/Desktop/progs/rsoi/env/lib/python3.7/site-packages/rest_framework/views.py", line 497, in dispatch
    response = self.handle_exception(exc)
  File "/Users/malenkijkotik/Desktop/progs/rsoi/env/lib/python3.7/site-packages/rest_framework/views.py", line 457, in handle_exception
    self.raise_uncaught_exception(exc)
  File "/Users/malenkijkotik/Desktop/progs/rsoi/env/lib/python3.7/site-packages/rest_framework/views.py", line 468, in raise_uncaught_exception
    raise exc
  File "/Users/malenkijkotik/Desktop/progs/rsoi/env/lib/python3.7/site-packages/rest_framework/views.py", line 494, in dispatch
    response = handler(request, *args, **kwargs)
  File "/Users/malenkijkotik/Desktop/progs/rsoi-online-store/online-store-customers/customers_app/views.py", line 138, in get
    if serializer.is_valid():
AttributeError: 'Customer' object has no attribute 'is_valid'
"GET /create_new_order/31/ HTTP/1.1" 500 15611
/Users/malenkijkotik/Desktop/progs/rsoi-online-store/online-store-customers/customers_app/views.py changed, reloading.
Watching for file changes with StatReloader
Internal Server Error: /create_new_order/31/
Traceback (most recent call last):
  File "/Users/malenkijkotik/Desktop/progs/rsoi/env/lib/python3.7/site-packages/django/core/handlers/exception.py", line 34, in inner
    response = get_response(request)
  File "/Users/malenkijkotik/Desktop/progs/rsoi/env/lib/python3.7/site-packages/django/core/handlers/base.py", line 115, in _get_response
    response = self.process_exception_by_middleware(e, request)
  File "/Users/malenkijkotik/Desktop/progs/rsoi/env/lib/python3.7/site-packages/django/core/handlers/base.py", line 113, in _get_response
    response = wrapped_callback(request, *callback_args, **callback_kwargs)
  File "/Users/malenkijkotik/Desktop/progs/rsoi/env/lib/python3.7/site-packages/django/views/decorators/csrf.py", line 54, in wrapped_view
    return view_func(*args, **kwargs)
  File "/Users/malenkijkotik/Desktop/progs/rsoi/env/lib/python3.7/site-packages/django/views/generic/base.py", line 71, in view
    return self.dispatch(request, *args, **kwargs)
  File "/Users/malenkijkotik/Desktop/progs/rsoi/env/lib/python3.7/site-packages/rest_framework/views.py", line 497, in dispatch
    response = self.handle_exception(exc)
  File "/Users/malenkijkotik/Desktop/progs/rsoi/env/lib/python3.7/site-packages/rest_framework/views.py", line 457, in handle_exception
    self.raise_uncaught_exception(exc)
  File "/Users/malenkijkotik/Desktop/progs/rsoi/env/lib/python3.7/site-packages/rest_framework/views.py", line 468, in raise_uncaught_exception
    raise exc
  File "/Users/malenkijkotik/Desktop/progs/rsoi/env/lib/python3.7/site-packages/rest_framework/views.py", line 494, in dispatch
    response = handler(request, *args, **kwargs)
  File "/Users/malenkijkotik/Desktop/progs/rsoi-online-store/online-store-customers/customers_app/views.py", line 140, in get
    return Response(serializer.data, status=status.HTTP_200_OK)
AttributeError: 'Customer' object has no attribute 'data'
"GET /create_new_order/31/ HTTP/1.1" 500 15637
/Users/malenkijkotik/Desktop/progs/rsoi-online-store/online-store-customers/customers_app/views.py changed, reloading.
Watching for file changes with StatReloader
Internal Server Error: /create_new_order/31/
Traceback (most recent call last):
  File "/Users/malenkijkotik/Desktop/progs/rsoi/env/lib/python3.7/site-packages/django/core/handlers/exception.py", line 34, in inner
    response = get_response(request)
  File "/Users/malenkijkotik/Desktop/progs/rsoi/env/lib/python3.7/site-packages/django/core/handlers/base.py", line 115, in _get_response
    response = self.process_exception_by_middleware(e, request)
  File "/Users/malenkijkotik/Desktop/progs/rsoi/env/lib/python3.7/site-packages/django/core/handlers/base.py", line 113, in _get_response
    response = wrapped_callback(request, *callback_args, **callback_kwargs)
  File "/Users/malenkijkotik/Desktop/progs/rsoi/env/lib/python3.7/site-packages/django/views/decorators/csrf.py", line 54, in wrapped_view
    return view_func(*args, **kwargs)
  File "/Users/malenkijkotik/Desktop/progs/rsoi/env/lib/python3.7/site-packages/django/views/generic/base.py", line 71, in view
    return self.dispatch(request, *args, **kwargs)
  File "/Users/malenkijkotik/Desktop/progs/rsoi/env/lib/python3.7/site-packages/rest_framework/views.py", line 497, in dispatch
    response = self.handle_exception(exc)
  File "/Users/malenkijkotik/Desktop/progs/rsoi/env/lib/python3.7/site-packages/rest_framework/views.py", line 457, in handle_exception
    self.raise_uncaught_exception(exc)
  File "/Users/malenkijkotik/Desktop/progs/rsoi/env/lib/python3.7/site-packages/rest_framework/views.py", line 468, in raise_uncaught_exception
    raise exc
  File "/Users/malenkijkotik/Desktop/progs/rsoi/env/lib/python3.7/site-packages/rest_framework/views.py", line 494, in dispatch
    response = handler(request, *args, **kwargs)
  File "/Users/malenkijkotik/Desktop/progs/rsoi-online-store/online-store-customers/customers_app/views.py", line 139, in get
    return Response(serializer.data, status=status.HTTP_200_OK)
AttributeError: 'Customer' object has no attribute 'data'
"GET /create_new_order/31/ HTTP/1.1" 500 15637
/Users/malenkijkotik/Desktop/progs/rsoi-online-store/online-store-customers/customers_app/views.py changed, reloading.
Watching for file changes with StatReloader
Internal Server Error: /create_new_order/31/
Traceback (most recent call last):
  File "/Users/malenkijkotik/Desktop/progs/rsoi/env/lib/python3.7/site-packages/django/core/handlers/exception.py", line 34, in inner
    response = get_response(request)
  File "/Users/malenkijkotik/Desktop/progs/rsoi/env/lib/python3.7/site-packages/django/core/handlers/base.py", line 115, in _get_response
    response = self.process_exception_by_middleware(e, request)
  File "/Users/malenkijkotik/Desktop/progs/rsoi/env/lib/python3.7/site-packages/django/core/handlers/base.py", line 113, in _get_response
    response = wrapped_callback(request, *callback_args, **callback_kwargs)
  File "/Users/malenkijkotik/Desktop/progs/rsoi/env/lib/python3.7/site-packages/django/views/decorators/csrf.py", line 54, in wrapped_view
    return view_func(*args, **kwargs)
  File "/Users/malenkijkotik/Desktop/progs/rsoi/env/lib/python3.7/site-packages/django/views/generic/base.py", line 71, in view
    return self.dispatch(request, *args, **kwargs)
  File "/Users/malenkijkotik/Desktop/progs/rsoi/env/lib/python3.7/site-packages/rest_framework/views.py", line 497, in dispatch
    response = self.handle_exception(exc)
  File "/Users/malenkijkotik/Desktop/progs/rsoi/env/lib/python3.7/site-packages/rest_framework/views.py", line 457, in handle_exception
    self.raise_uncaught_exception(exc)
  File "/Users/malenkijkotik/Desktop/progs/rsoi/env/lib/python3.7/site-packages/rest_framework/views.py", line 468, in raise_uncaught_exception
    raise exc
  File "/Users/malenkijkotik/Desktop/progs/rsoi/env/lib/python3.7/site-packages/rest_framework/views.py", line 494, in dispatch
    response = handler(request, *args, **kwargs)
  File "/Users/malenkijkotik/Desktop/progs/rsoi-online-store/online-store-customers/customers_app/views.py", line 140, in get
    return Response(serializer.data, status=status.HTTP_200_OK)
AttributeError: 'Customer' object has no attribute 'data'
"GET /create_new_order/31/ HTTP/1.1" 500 15637
Internal Server Error: /create_new_order/31/
Traceback (most recent call last):
  File "/Users/malenkijkotik/Desktop/progs/rsoi/env/lib/python3.7/site-packages/django/core/handlers/exception.py", line 34, in inner
    response = get_response(request)
  File "/Users/malenkijkotik/Desktop/progs/rsoi/env/lib/python3.7/site-packages/django/core/handlers/base.py", line 115, in _get_response
    response = self.process_exception_by_middleware(e, request)
  File "/Users/malenkijkotik/Desktop/progs/rsoi/env/lib/python3.7/site-packages/django/core/handlers/base.py", line 113, in _get_response
    response = wrapped_callback(request, *callback_args, **callback_kwargs)
  File "/Users/malenkijkotik/Desktop/progs/rsoi/env/lib/python3.7/site-packages/django/views/decorators/csrf.py", line 54, in wrapped_view
    return view_func(*args, **kwargs)
  File "/Users/malenkijkotik/Desktop/progs/rsoi/env/lib/python3.7/site-packages/django/views/generic/base.py", line 71, in view
    return self.dispatch(request, *args, **kwargs)
  File "/Users/malenkijkotik/Desktop/progs/rsoi/env/lib/python3.7/site-packages/rest_framework/views.py", line 497, in dispatch
    response = self.handle_exception(exc)
  File "/Users/malenkijkotik/Desktop/progs/rsoi/env/lib/python3.7/site-packages/rest_framework/views.py", line 457, in handle_exception
    self.raise_uncaught_exception(exc)
  File "/Users/malenkijkotik/Desktop/progs/rsoi/env/lib/python3.7/site-packages/rest_framework/views.py", line 468, in raise_uncaught_exception
    raise exc
  File "/Users/malenkijkotik/Desktop/progs/rsoi/env/lib/python3.7/site-packages/rest_framework/views.py", line 494, in dispatch
    response = handler(request, *args, **kwargs)
  File "/Users/malenkijkotik/Desktop/progs/rsoi-online-store/online-store-customers/customers_app/views.py", line 140, in get
    return Response(serializer.data, status=status.HTTP_200_OK)
AttributeError: 'Customer' object has no attribute 'data'
"GET /create_new_order/31/ HTTP/1.1" 500 15637
/Users/malenkijkotik/Desktop/progs/rsoi-online-store/online-store-customers/customers_app/views.py changed, reloading.
Watching for file changes with StatReloader
Internal Server Error: /create_new_order/31/
Traceback (most recent call last):
  File "/Users/malenkijkotik/Desktop/progs/rsoi/env/lib/python3.7/site-packages/django/core/handlers/exception.py", line 34, in inner
    response = get_response(request)
  File "/Users/malenkijkotik/Desktop/progs/rsoi/env/lib/python3.7/site-packages/django/core/handlers/base.py", line 145, in _get_response
    response = self.process_exception_by_middleware(e, request)
  File "/Users/malenkijkotik/Desktop/progs/rsoi/env/lib/python3.7/site-packages/django/core/handlers/base.py", line 143, in _get_response
    response = response.render()
  File "/Users/malenkijkotik/Desktop/progs/rsoi/env/lib/python3.7/site-packages/django/template/response.py", line 106, in render
    self.content = self.rendered_content
  File "/Users/malenkijkotik/Desktop/progs/rsoi/env/lib/python3.7/site-packages/rest_framework/response.py", line 70, in rendered_content
    ret = renderer.render(self.data, accepted_media_type, context)
  File "/Users/malenkijkotik/Desktop/progs/rsoi/env/lib/python3.7/site-packages/rest_framework/renderers.py", line 104, in render
    allow_nan=not self.strict, separators=separators
  File "/Users/malenkijkotik/Desktop/progs/rsoi/env/lib/python3.7/site-packages/rest_framework/utils/json.py", line 25, in dumps
    return json.dumps(*args, **kwargs)
  File "/Library/Frameworks/Python.framework/Versions/3.7/lib/python3.7/json/__init__.py", line 238, in dumps
    **kw).encode(obj)
  File "/Library/Frameworks/Python.framework/Versions/3.7/lib/python3.7/json/encoder.py", line 199, in encode
    chunks = self.iterencode(o, _one_shot=True)
  File "/Library/Frameworks/Python.framework/Versions/3.7/lib/python3.7/json/encoder.py", line 257, in iterencode
    return _iterencode(o, 0)
  File "/Users/malenkijkotik/Desktop/progs/rsoi/env/lib/python3.7/site-packages/rest_framework/utils/encoders.py", line 67, in default
    return super().default(obj)
  File "/Library/Frameworks/Python.framework/Versions/3.7/lib/python3.7/json/encoder.py", line 179, in default
    raise TypeError(f'Object of type {o.__class__.__name__} '
TypeError: Object of type Customer is not JSON serializable
"GET /create_new_order/31/ HTTP/1.1" 500 97873
/Users/malenkijkotik/Desktop/progs/rsoi-online-store/online-store-customers/customers_app/views.py changed, reloading.
Watching for file changes with StatReloader
Internal Server Error: /create_new_order/31/
Traceback (most recent call last):
  File "/Users/malenkijkotik/Desktop/progs/rsoi/env/lib/python3.7/site-packages/django/core/handlers/exception.py", line 34, in inner
    response = get_response(request)
  File "/Users/malenkijkotik/Desktop/progs/rsoi/env/lib/python3.7/site-packages/django/core/handlers/base.py", line 115, in _get_response
    response = self.process_exception_by_middleware(e, request)
  File "/Users/malenkijkotik/Desktop/progs/rsoi/env/lib/python3.7/site-packages/django/core/handlers/base.py", line 113, in _get_response
    response = wrapped_callback(request, *callback_args, **callback_kwargs)
  File "/Users/malenkijkotik/Desktop/progs/rsoi/env/lib/python3.7/site-packages/django/views/decorators/csrf.py", line 54, in wrapped_view
    return view_func(*args, **kwargs)
  File "/Users/malenkijkotik/Desktop/progs/rsoi/env/lib/python3.7/site-packages/django/views/generic/base.py", line 71, in view
    return self.dispatch(request, *args, **kwargs)
  File "/Users/malenkijkotik/Desktop/progs/rsoi/env/lib/python3.7/site-packages/rest_framework/views.py", line 497, in dispatch
    response = self.handle_exception(exc)
  File "/Users/malenkijkotik/Desktop/progs/rsoi/env/lib/python3.7/site-packages/rest_framework/views.py", line 457, in handle_exception
    self.raise_uncaught_exception(exc)
  File "/Users/malenkijkotik/Desktop/progs/rsoi/env/lib/python3.7/site-packages/rest_framework/views.py", line 468, in raise_uncaught_exception
    raise exc
  File "/Users/malenkijkotik/Desktop/progs/rsoi/env/lib/python3.7/site-packages/rest_framework/views.py", line 494, in dispatch
    response = handler(request, *args, **kwargs)
  File "/Users/malenkijkotik/Desktop/progs/rsoi-online-store/online-store-customers/customers_app/views.py", line 140, in get
    return Response(CustomerSerializer(instance=serializer), status=status.HTTP_200_OK)
  File "/Users/malenkijkotik/Desktop/progs/rsoi/env/lib/python3.7/site-packages/rest_framework/response.py", line 38, in __init__
    raise AssertionError(msg)
AssertionError: You passed a Serializer instance as data, but probably meant to pass serialized `.data` or `.error`. representation.
"GET /create_new_order/31/ HTTP/1.1" 500 15974
/Users/malenkijkotik/Desktop/progs/rsoi-online-store/online-store-customers/customers_app/views.py changed, reloading.
Watching for file changes with StatReloader
"GET /create_new_order/31/ HTTP/1.1" 200 416
"GET /all_customers/31/ HTTP/1.1" 200 1883
"GET /all_customers/ HTTP/1.1" 200 2563
Internal Server Error: /create_new_order/23/
Traceback (most recent call last):
  File "/Users/malenkijkotik/Desktop/progs/rsoi/env/lib/python3.7/site-packages/django/core/handlers/exception.py", line 34, in inner
    response = get_response(request)
  File "/Users/malenkijkotik/Desktop/progs/rsoi/env/lib/python3.7/site-packages/django/core/handlers/base.py", line 115, in _get_response
    response = self.process_exception_by_middleware(e, request)
  File "/Users/malenkijkotik/Desktop/progs/rsoi/env/lib/python3.7/site-packages/django/core/handlers/base.py", line 113, in _get_response
    response = wrapped_callback(request, *callback_args, **callback_kwargs)
  File "/Users/malenkijkotik/Desktop/progs/rsoi/env/lib/python3.7/site-packages/django/views/decorators/csrf.py", line 54, in wrapped_view
    return view_func(*args, **kwargs)
  File "/Users/malenkijkotik/Desktop/progs/rsoi/env/lib/python3.7/site-packages/django/views/generic/base.py", line 71, in view
    return self.dispatch(request, *args, **kwargs)
  File "/Users/malenkijkotik/Desktop/progs/rsoi/env/lib/python3.7/site-packages/rest_framework/views.py", line 497, in dispatch
    response = self.handle_exception(exc)
  File "/Users/malenkijkotik/Desktop/progs/rsoi/env/lib/python3.7/site-packages/rest_framework/views.py", line 457, in handle_exception
    self.raise_uncaught_exception(exc)
  File "/Users/malenkijkotik/Desktop/progs/rsoi/env/lib/python3.7/site-packages/rest_framework/views.py", line 468, in raise_uncaught_exception
    raise exc
  File "/Users/malenkijkotik/Desktop/progs/rsoi/env/lib/python3.7/site-packages/rest_framework/views.py", line 494, in dispatch
    response = handler(request, *args, **kwargs)
  File "/Users/malenkijkotik/Desktop/progs/rsoi-online-store/online-store-customers/customers_app/views.py", line 134, in get
    old_orders.append(new_order_uuid)
AttributeError: 'NoneType' object has no attribute 'append'
"GET /create_new_order/23/ HTTP/1.1" 500 15615
/Users/malenkijkotik/Desktop/progs/rsoi-online-store/online-store-customers/customers_app/views.py changed, reloading.
Watching for file changes with StatReloader
"GET /create_new_order/23/ HTTP/1.1" 200 93
"GET /create_new_order/23/ HTTP/1.1" 200 132
Watching for file changes with StatReloader
/Users/malenkijkotik/Desktop/progs/rsoi-online-store/online-store-customers/customers_app/requesters/orders_requesters.py changed, reloading.
Watching for file changes with StatReloader
"GET /create_new_order/23/ HTTP/1.1" 200 133
